2024-10-14 05:14:39,511 - INFO - API Key: OPENAI_API_KEY=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
PERPLEXITY_API_KEY=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
2024-10-14 05:14:39,535 - INFO - Skipping Prompt 1 (climate_change_impact): Output already exists.
2024-10-14 05:14:39,536 - INFO - Skipping Prompt 2 (colony_simulation_model): Output already exists.
2024-10-14 05:14:39,536 - INFO - Skipping Prompt 3 (navigation_breakthroughs): Output already exists.
2024-10-14 05:14:39,536 - INFO - Skipping Prompt 4 (invasive_species_economics): Output already exists.
2024-10-14 05:14:39,536 - INFO - Skipping Prompt 5 (crispr_gene_editing): Output already exists.
2024-10-14 05:14:39,536 - INFO - Skipping Prompt 6 (recent_new_species): Output already exists.
2024-10-14 05:14:39,537 - INFO - Skipping Prompt 7 (carbon_cycling_impact): Output already exists.
2024-10-14 05:14:39,537 - INFO - Skipping Prompt 8 (ant_inspired_algorithms): Output already exists.
2024-10-14 05:14:39,537 - INFO - Skipping Prompt 9 (supercolony_formation): Output already exists.
2024-10-14 05:14:39,537 - INFO - Skipping Prompt 10 (myrmecology_timeline): Output already exists.
2024-10-14 05:14:39,537 - INFO - Skipping Prompt 11 (parasite_arms_race): Output already exists.
2024-10-14 05:14:39,537 - INFO - Skipping Prompt 12 (urbanization_effects): Output already exists.
2024-10-14 05:14:39,538 - INFO - Skipping Prompt 13 (pharmaceutical_potential): Output already exists.
2024-10-14 05:14:39,538 - INFO - Skipping Prompt 14 (epigenetics_caste_determination): Output already exists.
2024-10-14 05:14:39,538 - INFO - Skipping Prompt 15 (tropical_ecosystem_interactions): Output already exists.
2024-10-14 05:14:39,538 - INFO - Skipping Prompt 16 (phylogenomic_analysis): Output already exists.
2024-10-14 05:14:39,538 - INFO - Skipping Prompt 17 (emerging_tech_impact): Output already exists.
2024-10-14 05:14:39,538 - INFO - Skipping Prompt 18 (conservation_assessment): Output already exists.
2024-10-14 05:14:39,538 - INFO - Skipping Prompt 19 (bioindicator_role): Output already exists.
2024-10-14 05:14:39,539 - INFO - Skipping Prompt 20 (swarm_intelligence_applications): Output already exists.
2024-10-14 05:14:39,539 - INFO - Skipping Prompt 21 (biogenic_amines_foraging): Output already exists.
2024-10-14 05:14:39,539 - INFO - Skipping Prompt 22 (brain_regions_foraging): Output already exists.
2024-10-14 05:14:39,539 - INFO - Skipping Prompt 23 (neural_variability_foraging): Output already exists.
2024-10-14 05:14:39,539 - INFO - Skipping Prompt 24 (deborah_gordon_meta_analysis): Output already exists.
2024-10-14 05:14:39,540 - INFO - Skipping Prompt 25 (tim_linksvayer_meta_analysis): Output already exists.
2024-10-14 05:14:39,540 - INFO - Skipping Prompt 26 (colony_behavior_relatedness): Output already exists.
2024-10-14 05:14:39,540 - INFO - Skipping Prompt 27 (nestmate_morphology_relatedness): Output already exists.
2024-10-14 05:14:39,540 - INFO - Skipping Prompt 28 (colony_behavior_genetic_correlation): Output already exists.
2024-10-14 05:14:39,540 - INFO - Skipping Prompt 29 (nestmate_behavior_relatedness): Output already exists.
2024-10-14 05:14:39,540 - INFO - Skipping Prompt 30 (colony_morphology_relatedness): Output already exists.
2024-10-14 05:14:39,541 - INFO - Skipping Prompt 31 (colony_behavior_morphology_relatedness): Output already exists.
2024-10-14 05:14:39,541 - INFO - Skipping Prompt 32 (nestmate_trait_relatedness_meta_analysis): Output already exists.
2024-10-14 05:14:39,541 - INFO - Skipping Prompt 33 (camponotus_recent_research): Output already exists.
2024-10-14 05:14:39,541 - INFO - Skipping Prompt 34 (formica_recent_studies): Output already exists.
2024-10-14 05:14:39,541 - INFO - Skipping Prompt 35 (pheidole_diversity_ecology): Output already exists.
2024-10-14 05:14:39,541 - INFO - Skipping Prompt 36 (atta_leafcutter_research): Output already exists.
2024-10-14 05:14:39,542 - INFO - Skipping Prompt 37 (solenopsis_fire_ant_studies): Output already exists.
2024-10-14 05:14:39,542 - INFO - Skipping Prompt 38 (monomorium_global_research): Output already exists.
2024-10-14 05:14:39,542 - INFO - Skipping Prompt 39 (lasius_ecosystem_interactions): Output already exists.
2024-10-14 05:14:39,542 - INFO - Skipping Prompt 40 (oecophylla_weaver_ant_research): Output already exists.
2024-10-14 05:14:39,542 - INFO - Skipping Prompt 41 (pogonomyrmex_barbatus_research): Output already exists.
2024-10-14 05:14:39,542 - INFO - Skipping Prompt 42 (non_barbatus_pogonomyrmex_studies): Output already exists.
2024-10-14 05:14:39,543 - INFO - Processing Prompt 43: Analyze recent research (2020-2024) on the impact ...
2024-10-14 05:14:39,709 - INFO - Retrying request to /chat/completions in 0.909928 seconds
2024-10-14 05:14:41,196 - INFO - Retrying request to /chat/completions in 1.973661 seconds
2024-10-14 05:14:43,555 - ERROR - Unexpected error processing Prompt 43: Connection error.
Traceback (most recent call last):
  File "/usr/lib/python3/dist-packages/httpcore/_exceptions.py", line 10, in map_exceptions
    yield
  File "/usr/lib/python3/dist-packages/httpcore/_sync/http11.py", line 121, in _send_request_headers
    event = h11.Request(
            ^^^^^^^^^^^^
  File "/usr/lib/python3/dist-packages/h11/_events.py", line 96, in __init__
    self, "headers", normalize_and_validate(headers, _parsed=_parsed)
                     ^^^^^^^^^^^^^^^^^^^^^^^^^^^^^^^^^^^^^^^^^^^^^^^^
  File "/usr/lib/python3/dist-packages/h11/_headers.py", line 164, in normalize_and_validate
    validate(_field_value_re, value, "Illegal header value {!r}", value)
  File "/usr/lib/python3/dist-packages/h11/_util.py", line 91, in validate
    raise LocalProtocolError(msg)
h11._util.LocalProtocolError: Illegal header value b'Bearer OPENAI_API_KEY=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\nPERPLEXITY_API_KEY=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'

During handling of the above exception, another exception occurred:

Traceback (most recent call last):
  File "/usr/lib/python3/dist-packages/httpx/_transports/default.py", line 60, in map_httpcore_exceptions
    yield
  File "/usr/lib/python3/dist-packages/httpx/_transports/default.py", line 218, in handle_request
    resp = self._pool.handle_request(req)
           ^^^^^^^^^^^^^^^^^^^^^^^^^^^^^^
  File "/usr/lib/python3/dist-packages/httpcore/_sync/connection_pool.py", line 253, in handle_request
    raise exc
  File "/usr/lib/python3/dist-packages/httpcore/_sync/connection_pool.py", line 237, in handle_request
    response = connection.handle_request(request)
               ^^^^^^^^^^^^^^^^^^^^^^^^^^^^^^^^^^
  File "/usr/lib/python3/dist-packages/httpcore/_sync/connection.py", line 90, in handle_request
    return self._connection.handle_request(request)
           ^^^^^^^^^^^^^^^^^^^^^^^^^^^^^^^^^^^^^^^^
  File "/usr/lib/python3/dist-packages/httpcore/_sync/http11.py", line 112, in handle_request
    raise exc
  File "/usr/lib/python3/dist-packages/httpcore/_sync/http11.py", line 80, in handle_request
    self._send_request_headers(**kwargs)
  File "/usr/lib/python3/dist-packages/httpcore/_sync/http11.py", line 120, in _send_request_headers
    with map_exceptions({h11.LocalProtocolError: LocalProtocolError}):
  File "/usr/lib/python3.11/contextlib.py", line 155, in __exit__
    self.gen.throw(typ, value, traceback)
  File "/usr/lib/python3/dist-packages/httpcore/_exceptions.py", line 14, in map_exceptions
    raise to_exc(exc)
httpcore.LocalProtocolError: Illegal header value b'Bearer OPENAI_API_KEY=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\nPERPLEXITY_API_KEY=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'

The above exception was the direct cause of the following exception:

Traceback (most recent call last):
  File "/home/trim/.local/lib/python3.11/site-packages/openai/_base_client.py", line 972, in _request
    response = self._client.send(
               ^^^^^^^^^^^^^^^^^^
  File "/usr/lib/python3/dist-packages/httpx/_client.py", line 908, in send
    response = self._send_handling_auth(
               ^^^^^^^^^^^^^^^^^^^^^^^^^
  File "/usr/lib/python3/dist-packages/httpx/_client.py", line 936, in _send_handling_auth
    response = self._send_handling_redirects(
               ^^^^^^^^^^^^^^^^^^^^^^^^^^^^^^
  File "/usr/lib/python3/dist-packages/httpx/_client.py", line 973, in _send_handling_redirects
    response = self._send_single_request(request)
               ^^^^^^^^^^^^^^^^^^^^^^^^^^^^^^^^^^
  File "/usr/lib/python3/dist-packages/httpx/_client.py", line 1009, in _send_single_request
    response = transport.handle_request(request)
               ^^^^^^^^^^^^^^^^^^^^^^^^^^^^^^^^^
  File "/usr/lib/python3/dist-packages/httpx/_transports/default.py", line 217, in handle_request
    with map_httpcore_exceptions():
  File "/usr/lib/python3.11/contextlib.py", line 155, in __exit__
    self.gen.throw(typ, value, traceback)
  File "/usr/lib/python3/dist-packages/httpx/_transports/default.py", line 77, in map_httpcore_exceptions
    raise mapped_exc(message) from exc
httpx.LocalProtocolError: Illegal header value b'Bearer OPENAI_API_KEY=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\nPERPLEXITY_API_KEY=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'

During handling of the above exception, another exception occurred:

Traceback (most recent call last):
  File "/usr/lib/python3/dist-packages/httpcore/_exceptions.py", line 10, in map_exceptions
    yield
  File "/usr/lib/python3/dist-packages/httpcore/_sync/http11.py", line 121, in _send_request_headers
    event = h11.Request(
            ^^^^^^^^^^^^
  File "/usr/lib/python3/dist-packages/h11/_events.py", line 96, in __init__
    self, "headers", normalize_and_validate(headers, _parsed=_parsed)
                     ^^^^^^^^^^^^^^^^^^^^^^^^^^^^^^^^^^^^^^^^^^^^^^^^
  File "/usr/lib/python3/dist-packages/h11/_headers.py", line 164, in normalize_and_validate
    validate(_field_value_re, value, "Illegal header value {!r}", value)
  File "/usr/lib/python3/dist-packages/h11/_util.py", line 91, in validate
    raise LocalProtocolError(msg)
h11._util.LocalProtocolError: Illegal header value b'Bearer OPENAI_API_KEY=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\nPERPLEXITY_API_KEY=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'

During handling of the above exception, another exception occurred:

Traceback (most recent call last):
  File "/usr/lib/python3/dist-packages/httpx/_transports/default.py", line 60, in map_httpcore_exceptions
    yield
  File "/usr/lib/python3/dist-packages/httpx/_transports/default.py", line 218, in handle_request
    resp = self._pool.handle_request(req)
           ^^^^^^^^^^^^^^^^^^^^^^^^^^^^^^
  File "/usr/lib/python3/dist-packages/httpcore/_sync/connection_pool.py", line 253, in handle_request
    raise exc
  File "/usr/lib/python3/dist-packages/httpcore/_sync/connection_pool.py", line 237, in handle_request
    response = connection.handle_request(request)
               ^^^^^^^^^^^^^^^^^^^^^^^^^^^^^^^^^^
  File "/usr/lib/python3/dist-packages/httpcore/_sync/connection.py", line 90, in handle_request
    return self._connection.handle_request(request)
           ^^^^^^^^^^^^^^^^^^^^^^^^^^^^^^^^^^^^^^^^
  File "/usr/lib/python3/dist-packages/httpcore/_sync/http11.py", line 112, in handle_request
    raise exc
  File "/usr/lib/python3/dist-packages/httpcore/_sync/http11.py", line 80, in handle_request
    self._send_request_headers(**kwargs)
  File "/usr/lib/python3/dist-packages/httpcore/_sync/http11.py", line 120, in _send_request_headers
    with map_exceptions({h11.LocalProtocolError: LocalProtocolError}):
  File "/usr/lib/python3.11/contextlib.py", line 155, in __exit__
    self.gen.throw(typ, value, traceback)
  File "/usr/lib/python3/dist-packages/httpcore/_exceptions.py", line 14, in map_exceptions
    raise to_exc(exc)
httpcore.LocalProtocolError: Illegal header value b'Bearer OPENAI_API_KEY=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\nPERPLEXITY_API_KEY=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'

The above exception was the direct cause of the following exception:

Traceback (most recent call last):
  File "/home/trim/.local/lib/python3.11/site-packages/openai/_base_client.py", line 972, in _request
    response = self._client.send(
               ^^^^^^^^^^^^^^^^^^
  File "/usr/lib/python3/dist-packages/httpx/_client.py", line 908, in send
    response = self._send_handling_auth(
               ^^^^^^^^^^^^^^^^^^^^^^^^^
  File "/usr/lib/python3/dist-packages/httpx/_client.py", line 936, in _send_handling_auth
    response = self._send_handling_redirects(
               ^^^^^^^^^^^^^^^^^^^^^^^^^^^^^^
  File "/usr/lib/python3/dist-packages/httpx/_client.py", line 973, in _send_handling_redirects
    response = self._send_single_request(request)
               ^^^^^^^^^^^^^^^^^^^^^^^^^^^^^^^^^^
  File "/usr/lib/python3/dist-packages/httpx/_client.py", line 1009, in _send_single_request
    response = transport.handle_request(request)
               ^^^^^^^^^^^^^^^^^^^^^^^^^^^^^^^^^
  File "/usr/lib/python3/dist-packages/httpx/_transports/default.py", line 217, in handle_request
    with map_httpcore_exceptions():
  File "/usr/lib/python3.11/contextlib.py", line 155, in __exit__
    self.gen.throw(typ, value, traceback)
  File "/usr/lib/python3/dist-packages/httpx/_transports/default.py", line 77, in map_httpcore_exceptions
    raise mapped_exc(message) from exc
httpx.LocalProtocolError: Illegal header value b'Bearer OPENAI_API_KEY=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\nPERPLEXITY_API_KEY=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'

During handling of the above exception, another exception occurred:

Traceback (most recent call last):
  File "/usr/lib/python3/dist-packages/httpcore/_exceptions.py", line 10, in map_exceptions
    yield
  File "/usr/lib/python3/dist-packages/httpcore/_sync/http11.py", line 121, in _send_request_headers
    event = h11.Request(
            ^^^^^^^^^^^^
  File "/usr/lib/python3/dist-packages/h11/_events.py", line 96, in __init__
    self, "headers", normalize_and_validate(headers, _parsed=_parsed)
                     ^^^^^^^^^^^^^^^^^^^^^^^^^^^^^^^^^^^^^^^^^^^^^^^^
  File "/usr/lib/python3/dist-packages/h11/_headers.py", line 164, in normalize_and_validate
    validate(_field_value_re, value, "Illegal header value {!r}", value)
  File "/usr/lib/python3/dist-packages/h11/_util.py", line 91, in validate
    raise LocalProtocolError(msg)
h11._util.LocalProtocolError: Illegal header value b'Bearer OPENAI_API_KEY=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\nPERPLEXITY_API_KEY=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'

During handling of the above exception, another exception occurred:

Traceback (most recent call last):
  File "/usr/lib/python3/dist-packages/httpx/_transports/default.py", line 60, in map_httpcore_exceptions
    yield
  File "/usr/lib/python3/dist-packages/httpx/_transports/default.py", line 218, in handle_request
    resp = self._pool.handle_request(req)
           ^^^^^^^^^^^^^^^^^^^^^^^^^^^^^^
  File "/usr/lib/python3/dist-packages/httpcore/_sync/connection_pool.py", line 253, in handle_request
    raise exc
  File "/usr/lib/python3/dist-packages/httpcore/_sync/connection_pool.py", line 237, in handle_request
    response = connection.handle_request(request)
               ^^^^^^^^^^^^^^^^^^^^^^^^^^^^^^^^^^
  File "/usr/lib/python3/dist-packages/httpcore/_sync/connection.py", line 90, in handle_request
    return self._connection.handle_request(request)
           ^^^^^^^^^^^^^^^^^^^^^^^^^^^^^^^^^^^^^^^^
  File "/usr/lib/python3/dist-packages/httpcore/_sync/http11.py", line 112, in handle_request
    raise exc
  File "/usr/lib/python3/dist-packages/httpcore/_sync/http11.py", line 80, in handle_request
    self._send_request_headers(**kwargs)
  File "/usr/lib/python3/dist-packages/httpcore/_sync/http11.py", line 120, in _send_request_headers
    with map_exceptions({h11.LocalProtocolError: LocalProtocolError}):
  File "/usr/lib/python3.11/contextlib.py", line 155, in __exit__
    self.gen.throw(typ, value, traceback)
  File "/usr/lib/python3/dist-packages/httpcore/_exceptions.py", line 14, in map_exceptions
    raise to_exc(exc)
httpcore.LocalProtocolError: Illegal header value b'Bearer OPENAI_API_KEY=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\nPERPLEXITY_API_KEY=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'

The above exception was the direct cause of the following exception:

Traceback (most recent call last):
  File "/home/trim/.local/lib/python3.11/site-packages/openai/_base_client.py", line 972, in _request
    response = self._client.send(
               ^^^^^^^^^^^^^^^^^^
  File "/usr/lib/python3/dist-packages/httpx/_client.py", line 908, in send
    response = self._send_handling_auth(
               ^^^^^^^^^^^^^^^^^^^^^^^^^
  File "/usr/lib/python3/dist-packages/httpx/_client.py", line 936, in _send_handling_auth
    response = self._send_handling_redirects(
               ^^^^^^^^^^^^^^^^^^^^^^^^^^^^^^
  File "/usr/lib/python3/dist-packages/httpx/_client.py", line 973, in _send_handling_redirects
    response = self._send_single_request(request)
               ^^^^^^^^^^^^^^^^^^^^^^^^^^^^^^^^^^
  File "/usr/lib/python3/dist-packages/httpx/_client.py", line 1009, in _send_single_request
    response = transport.handle_request(request)
               ^^^^^^^^^^^^^^^^^^^^^^^^^^^^^^^^^
  File "/usr/lib/python3/dist-packages/httpx/_transports/default.py", line 217, in handle_request
    with map_httpcore_exceptions():
  File "/usr/lib/python3.11/contextlib.py", line 155, in __exit__
    self.gen.throw(typ, value, traceback)
  File "/usr/lib/python3/dist-packages/httpx/_transports/default.py", line 77, in map_httpcore_exceptions
    raise mapped_exc(message) from exc
httpx.LocalProtocolError: Illegal header value b'Bearer OPENAI_API_KEY=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\nPERPLEXITY_API_KEY=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'

The above exception was the direct cause of the following exception:

Traceback (most recent call last):
  File "/home/trim/Documents/GitHub/FORMINDEX/Perplexity_Methods/Perplexity.py", line 122, in <module>
    response = client.chat.completions.create(
               ^^^^^^^^^^^^^^^^^^^^^^^^^^^^^^^
  File "/home/trim/.local/lib/python3.11/site-packages/openai/_utils/_utils.py", line 274, in wrapper
    return func(*args, **kwargs)
           ^^^^^^^^^^^^^^^^^^^^^
  File "/home/trim/.local/lib/python3.11/site-packages/openai/resources/chat/completions.py", line 668, in create
    return self._post(
           ^^^^^^^^^^^
  File "/home/trim/.local/lib/python3.11/site-packages/openai/_base_client.py", line 1259, in post
    return cast(ResponseT, self.request(cast_to, opts, stream=stream, stream_cls=stream_cls))
                           ^^^^^^^^^^^^^^^^^^^^^^^^^^^^^^^^^^^^^^^^^^^^^^^^^^^^^^^^^^^^^^^^^
  File "/home/trim/.local/lib/python3.11/site-packages/openai/_base_client.py", line 936, in request
    return self._request(
           ^^^^^^^^^^^^^^
  File "/home/trim/.local/lib/python3.11/site-packages/openai/_base_client.py", line 996, in _request
    return self._retry_request(
           ^^^^^^^^^^^^^^^^^^^^
  File "/home/trim/.local/lib/python3.11/site-packages/openai/_base_client.py", line 1074, in _retry_request
    return self._request(
           ^^^^^^^^^^^^^^
  File "/home/trim/.local/lib/python3.11/site-packages/openai/_base_client.py", line 996, in _request
    return self._retry_request(
           ^^^^^^^^^^^^^^^^^^^^
  File "/home/trim/.local/lib/python3.11/site-packages/openai/_base_client.py", line 1074, in _retry_request
    return self._request(
           ^^^^^^^^^^^^^^
  File "/home/trim/.local/lib/python3.11/site-packages/openai/_base_client.py", line 1006, in _request
    raise APIConnectionError(request=request) from err
openai.APIConnectionError: Connection error.
2024-10-14 05:14:46,561 - INFO - Processing Prompt 44: Review recent studies (2020-2024) on the effects o...
2024-10-14 05:14:46,670 - INFO - Retrying request to /chat/completions in 0.973970 seconds
2024-10-14 05:14:47,792 - INFO - Retrying request to /chat/completions in 1.905633 seconds
2024-10-14 05:14:50,007 - ERROR - Unexpected error processing Prompt 44: Connection error.
Traceback (most recent call last):
  File "/usr/lib/python3/dist-packages/httpcore/_exceptions.py", line 10, in map_exceptions
    yield
  File "/usr/lib/python3/dist-packages/httpcore/_sync/http11.py", line 121, in _send_request_headers
    event = h11.Request(
            ^^^^^^^^^^^^
  File "/usr/lib/python3/dist-packages/h11/_events.py", line 96, in __init__
    self, "headers", normalize_and_validate(headers, _parsed=_parsed)
                     ^^^^^^^^^^^^^^^^^^^^^^^^^^^^^^^^^^^^^^^^^^^^^^^^
  File "/usr/lib/python3/dist-packages/h11/_headers.py", line 164, in normalize_and_validate
    validate(_field_value_re, value, "Illegal header value {!r}", value)
  File "/usr/lib/python3/dist-packages/h11/_util.py", line 91, in validate
    raise LocalProtocolError(msg)
h11._util.LocalProtocolError: Illegal header value b'Bearer OPENAI_API_KEY=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\nPERPLEXITY_API_KEY=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'

During handling of the above exception, another exception occurred:

Traceback (most recent call last):
  File "/usr/lib/python3/dist-packages/httpx/_transports/default.py", line 60, in map_httpcore_exceptions
    yield
  File "/usr/lib/python3/dist-packages/httpx/_transports/default.py", line 218, in handle_request
    resp = self._pool.handle_request(req)
           ^^^^^^^^^^^^^^^^^^^^^^^^^^^^^^
  File "/usr/lib/python3/dist-packages/httpcore/_sync/connection_pool.py", line 253, in handle_request
    raise exc
  File "/usr/lib/python3/dist-packages/httpcore/_sync/connection_pool.py", line 237, in handle_request
    response = connection.handle_request(request)
               ^^^^^^^^^^^^^^^^^^^^^^^^^^^^^^^^^^
  File "/usr/lib/python3/dist-packages/httpcore/_sync/connection.py", line 90, in handle_request
    return self._connection.handle_request(request)
           ^^^^^^^^^^^^^^^^^^^^^^^^^^^^^^^^^^^^^^^^
  File "/usr/lib/python3/dist-packages/httpcore/_sync/http11.py", line 112, in handle_request
    raise exc
  File "/usr/lib/python3/dist-packages/httpcore/_sync/http11.py", line 80, in handle_request
    self._send_request_headers(**kwargs)
  File "/usr/lib/python3/dist-packages/httpcore/_sync/http11.py", line 120, in _send_request_headers
    with map_exceptions({h11.LocalProtocolError: LocalProtocolError}):
  File "/usr/lib/python3.11/contextlib.py", line 155, in __exit__
    self.gen.throw(typ, value, traceback)
  File "/usr/lib/python3/dist-packages/httpcore/_exceptions.py", line 14, in map_exceptions
    raise to_exc(exc)
httpcore.LocalProtocolError: Illegal header value b'Bearer OPENAI_API_KEY=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\nPERPLEXITY_API_KEY=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'

The above exception was the direct cause of the following exception:

Traceback (most recent call last):
  File "/home/trim/.local/lib/python3.11/site-packages/openai/_base_client.py", line 972, in _request
    response = self._client.send(
               ^^^^^^^^^^^^^^^^^^
  File "/usr/lib/python3/dist-packages/httpx/_client.py", line 908, in send
    response = self._send_handling_auth(
               ^^^^^^^^^^^^^^^^^^^^^^^^^
  File "/usr/lib/python3/dist-packages/httpx/_client.py", line 936, in _send_handling_auth
    response = self._send_handling_redirects(
               ^^^^^^^^^^^^^^^^^^^^^^^^^^^^^^
  File "/usr/lib/python3/dist-packages/httpx/_client.py", line 973, in _send_handling_redirects
    response = self._send_single_request(request)
               ^^^^^^^^^^^^^^^^^^^^^^^^^^^^^^^^^^
  File "/usr/lib/python3/dist-packages/httpx/_client.py", line 1009, in _send_single_request
    response = transport.handle_request(request)
               ^^^^^^^^^^^^^^^^^^^^^^^^^^^^^^^^^
  File "/usr/lib/python3/dist-packages/httpx/_transports/default.py", line 217, in handle_request
    with map_httpcore_exceptions():
  File "/usr/lib/python3.11/contextlib.py", line 155, in __exit__
    self.gen.throw(typ, value, traceback)
  File "/usr/lib/python3/dist-packages/httpx/_transports/default.py", line 77, in map_httpcore_exceptions
    raise mapped_exc(message) from exc
httpx.LocalProtocolError: Illegal header value b'Bearer OPENAI_API_KEY=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\nPERPLEXITY_API_KEY=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'

During handling of the above exception, another exception occurred:

Traceback (most recent call last):
  File "/usr/lib/python3/dist-packages/httpcore/_exceptions.py", line 10, in map_exceptions
    yield
  File "/usr/lib/python3/dist-packages/httpcore/_sync/http11.py", line 121, in _send_request_headers
    event = h11.Request(
            ^^^^^^^^^^^^
  File "/usr/lib/python3/dist-packages/h11/_events.py", line 96, in __init__
    self, "headers", normalize_and_validate(headers, _parsed=_parsed)
                     ^^^^^^^^^^^^^^^^^^^^^^^^^^^^^^^^^^^^^^^^^^^^^^^^
  File "/usr/lib/python3/dist-packages/h11/_headers.py", line 164, in normalize_and_validate
    validate(_field_value_re, value, "Illegal header value {!r}", value)
  File "/usr/lib/python3/dist-packages/h11/_util.py", line 91, in validate
    raise LocalProtocolError(msg)
h11._util.LocalProtocolError: Illegal header value b'Bearer OPENAI_API_KEY=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\nPERPLEXITY_API_KEY=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'

During handling of the above exception, another exception occurred:

Traceback (most recent call last):
  File "/usr/lib/python3/dist-packages/httpx/_transports/default.py", line 60, in map_httpcore_exceptions
    yield
  File "/usr/lib/python3/dist-packages/httpx/_transports/default.py", line 218, in handle_request
    resp = self._pool.handle_request(req)
           ^^^^^^^^^^^^^^^^^^^^^^^^^^^^^^
  File "/usr/lib/python3/dist-packages/httpcore/_sync/connection_pool.py", line 253, in handle_request
    raise exc
  File "/usr/lib/python3/dist-packages/httpcore/_sync/connection_pool.py", line 237, in handle_request
    response = connection.handle_request(request)
               ^^^^^^^^^^^^^^^^^^^^^^^^^^^^^^^^^^
  File "/usr/lib/python3/dist-packages/httpcore/_sync/connection.py", line 90, in handle_request
    return self._connection.handle_request(request)
           ^^^^^^^^^^^^^^^^^^^^^^^^^^^^^^^^^^^^^^^^
  File "/usr/lib/python3/dist-packages/httpcore/_sync/http11.py", line 112, in handle_request
    raise exc
  File "/usr/lib/python3/dist-packages/httpcore/_sync/http11.py", line 80, in handle_request
    self._send_request_headers(**kwargs)
  File "/usr/lib/python3/dist-packages/httpcore/_sync/http11.py", line 120, in _send_request_headers
    with map_exceptions({h11.LocalProtocolError: LocalProtocolError}):
  File "/usr/lib/python3.11/contextlib.py", line 155, in __exit__
    self.gen.throw(typ, value, traceback)
  File "/usr/lib/python3/dist-packages/httpcore/_exceptions.py", line 14, in map_exceptions
    raise to_exc(exc)
httpcore.LocalProtocolError: Illegal header value b'Bearer OPENAI_API_KEY=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\nPERPLEXITY_API_KEY=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'

The above exception was the direct cause of the following exception:

Traceback (most recent call last):
  File "/home/trim/.local/lib/python3.11/site-packages/openai/_base_client.py", line 972, in _request
    response = self._client.send(
               ^^^^^^^^^^^^^^^^^^
  File "/usr/lib/python3/dist-packages/httpx/_client.py", line 908, in send
    response = self._send_handling_auth(
               ^^^^^^^^^^^^^^^^^^^^^^^^^
  File "/usr/lib/python3/dist-packages/httpx/_client.py", line 936, in _send_handling_auth
    response = self._send_handling_redirects(
               ^^^^^^^^^^^^^^^^^^^^^^^^^^^^^^
  File "/usr/lib/python3/dist-packages/httpx/_client.py", line 973, in _send_handling_redirects
    response = self._send_single_request(request)
               ^^^^^^^^^^^^^^^^^^^^^^^^^^^^^^^^^^
  File "/usr/lib/python3/dist-packages/httpx/_client.py", line 1009, in _send_single_request
    response = transport.handle_request(request)
               ^^^^^^^^^^^^^^^^^^^^^^^^^^^^^^^^^
  File "/usr/lib/python3/dist-packages/httpx/_transports/default.py", line 217, in handle_request
    with map_httpcore_exceptions():
  File "/usr/lib/python3.11/contextlib.py", line 155, in __exit__
    self.gen.throw(typ, value, traceback)
  File "/usr/lib/python3/dist-packages/httpx/_transports/default.py", line 77, in map_httpcore_exceptions
    raise mapped_exc(message) from exc
httpx.LocalProtocolError: Illegal header value b'Bearer OPENAI_API_KEY=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\nPERPLEXITY_API_KEY=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'

During handling of the above exception, another exception occurred:

Traceback (most recent call last):
  File "/usr/lib/python3/dist-packages/httpcore/_exceptions.py", line 10, in map_exceptions
    yield
  File "/usr/lib/python3/dist-packages/httpcore/_sync/http11.py", line 121, in _send_request_headers
    event = h11.Request(
            ^^^^^^^^^^^^
  File "/usr/lib/python3/dist-packages/h11/_events.py", line 96, in __init__
    self, "headers", normalize_and_validate(headers, _parsed=_parsed)
                     ^^^^^^^^^^^^^^^^^^^^^^^^^^^^^^^^^^^^^^^^^^^^^^^^
  File "/usr/lib/python3/dist-packages/h11/_headers.py", line 164, in normalize_and_validate
    validate(_field_value_re, value, "Illegal header value {!r}", value)
  File "/usr/lib/python3/dist-packages/h11/_util.py", line 91, in validate
    raise LocalProtocolError(msg)
h11._util.LocalProtocolError: Illegal header value b'Bearer OPENAI_API_KEY=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\nPERPLEXITY_API_KEY=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'

During handling of the above exception, another exception occurred:

Traceback (most recent call last):
  File "/usr/lib/python3/dist-packages/httpx/_transports/default.py", line 60, in map_httpcore_exceptions
    yield
  File "/usr/lib/python3/dist-packages/httpx/_transports/default.py", line 218, in handle_request
    resp = self._pool.handle_request(req)
           ^^^^^^^^^^^^^^^^^^^^^^^^^^^^^^
  File "/usr/lib/python3/dist-packages/httpcore/_sync/connection_pool.py", line 253, in handle_request
    raise exc
  File "/usr/lib/python3/dist-packages/httpcore/_sync/connection_pool.py", line 237, in handle_request
    response = connection.handle_request(request)
               ^^^^^^^^^^^^^^^^^^^^^^^^^^^^^^^^^^
  File "/usr/lib/python3/dist-packages/httpcore/_sync/connection.py", line 90, in handle_request
    return self._connection.handle_request(request)
           ^^^^^^^^^^^^^^^^^^^^^^^^^^^^^^^^^^^^^^^^
  File "/usr/lib/python3/dist-packages/httpcore/_sync/http11.py", line 112, in handle_request
    raise exc
  File "/usr/lib/python3/dist-packages/httpcore/_sync/http11.py", line 80, in handle_request
    self._send_request_headers(**kwargs)
  File "/usr/lib/python3/dist-packages/httpcore/_sync/http11.py", line 120, in _send_request_headers
    with map_exceptions({h11.LocalProtocolError: LocalProtocolError}):
  File "/usr/lib/python3.11/contextlib.py", line 155, in __exit__
    self.gen.throw(typ, value, traceback)
  File "/usr/lib/python3/dist-packages/httpcore/_exceptions.py", line 14, in map_exceptions
    raise to_exc(exc)
httpcore.LocalProtocolError: Illegal header value b'Bearer OPENAI_API_KEY=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\nPERPLEXITY_API_KEY=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'

The above exception was the direct cause of the following exception:

Traceback (most recent call last):
  File "/home/trim/.local/lib/python3.11/site-packages/openai/_base_client.py", line 972, in _request
    response = self._client.send(
               ^^^^^^^^^^^^^^^^^^
  File "/usr/lib/python3/dist-packages/httpx/_client.py", line 908, in send
    response = self._send_handling_auth(
               ^^^^^^^^^^^^^^^^^^^^^^^^^
  File "/usr/lib/python3/dist-packages/httpx/_client.py", line 936, in _send_handling_auth
    response = self._send_handling_redirects(
               ^^^^^^^^^^^^^^^^^^^^^^^^^^^^^^
  File "/usr/lib/python3/dist-packages/httpx/_client.py", line 973, in _send_handling_redirects
    response = self._send_single_request(request)
               ^^^^^^^^^^^^^^^^^^^^^^^^^^^^^^^^^^
  File "/usr/lib/python3/dist-packages/httpx/_client.py", line 1009, in _send_single_request
    response = transport.handle_request(request)
               ^^^^^^^^^^^^^^^^^^^^^^^^^^^^^^^^^
  File "/usr/lib/python3/dist-packages/httpx/_transports/default.py", line 217, in handle_request
    with map_httpcore_exceptions():
  File "/usr/lib/python3.11/contextlib.py", line 155, in __exit__
    self.gen.throw(typ, value, traceback)
  File "/usr/lib/python3/dist-packages/httpx/_transports/default.py", line 77, in map_httpcore_exceptions
    raise mapped_exc(message) from exc
httpx.LocalProtocolError: Illegal header value b'Bearer OPENAI_API_KEY=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\nPERPLEXITY_API_KEY=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'

The above exception was the direct cause of the following exception:

Traceback (most recent call last):
  File "/home/trim/Documents/GitHub/FORMINDEX/Perplexity_Methods/Perplexity.py", line 122, in <module>
    response = client.chat.completions.create(
               ^^^^^^^^^^^^^^^^^^^^^^^^^^^^^^^
  File "/home/trim/.local/lib/python3.11/site-packages/openai/_utils/_utils.py", line 274, in wrapper
    return func(*args, **kwargs)
           ^^^^^^^^^^^^^^^^^^^^^
  File "/home/trim/.local/lib/python3.11/site-packages/openai/resources/chat/completions.py", line 668, in create
    return self._post(
           ^^^^^^^^^^^
  File "/home/trim/.local/lib/python3.11/site-packages/openai/_base_client.py", line 1259, in post
    return cast(ResponseT, self.request(cast_to, opts, stream=stream, stream_cls=stream_cls))
                           ^^^^^^^^^^^^^^^^^^^^^^^^^^^^^^^^^^^^^^^^^^^^^^^^^^^^^^^^^^^^^^^^^
  File "/home/trim/.local/lib/python3.11/site-packages/openai/_base_client.py", line 936, in request
    return self._request(
           ^^^^^^^^^^^^^^
  File "/home/trim/.local/lib/python3.11/site-packages/openai/_base_client.py", line 996, in _request
    return self._retry_request(
           ^^^^^^^^^^^^^^^^^^^^
  File "/home/trim/.local/lib/python3.11/site-packages/openai/_base_client.py", line 1074, in _retry_request
    return self._request(
           ^^^^^^^^^^^^^^
  File "/home/trim/.local/lib/python3.11/site-packages/openai/_base_client.py", line 996, in _request
    return self._retry_request(
           ^^^^^^^^^^^^^^^^^^^^
  File "/home/trim/.local/lib/python3.11/site-packages/openai/_base_client.py", line 1074, in _retry_request
    return self._request(
           ^^^^^^^^^^^^^^
  File "/home/trim/.local/lib/python3.11/site-packages/openai/_base_client.py", line 1006, in _request
    raise APIConnectionError(request=request) from err
openai.APIConnectionError: Connection error.
2024-10-14 05:14:53,010 - INFO - Processing Prompt 45: Conduct a meta-analysis of research from 2020-2024...
2024-10-14 05:14:53,145 - INFO - Retrying request to /chat/completions in 0.857864 seconds
2024-10-14 05:14:54,098 - INFO - Retrying request to /chat/completions in 1.823563 seconds
2024-10-14 08:04:33,419 - INFO - API Key: OPENAI_API_KEY=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
PERPLEXITY_API_KEY=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
2024-10-14 08:04:33,444 - INFO - Skipping Prompt 1 (climate_change_impact): Output already exists.
2024-10-14 08:04:33,445 - INFO - Skipping Prompt 2 (colony_simulation_model): Output already exists.
2024-10-14 08:04:33,445 - INFO - Skipping Prompt 3 (navigation_breakthroughs): Output already exists.
2024-10-14 08:04:33,445 - INFO - Skipping Prompt 4 (invasive_species_economics): Output already exists.
2024-10-14 08:04:33,445 - INFO - Skipping Prompt 5 (crispr_gene_editing): Output already exists.
2024-10-14 08:04:33,446 - INFO - Skipping Prompt 6 (recent_new_species): Output already exists.
2024-10-14 08:04:33,446 - INFO - Skipping Prompt 7 (carbon_cycling_impact): Output already exists.
2024-10-14 08:04:33,446 - INFO - Skipping Prompt 8 (ant_inspired_algorithms): Output already exists.
2024-10-14 08:04:33,446 - INFO - Skipping Prompt 9 (supercolony_formation): Output already exists.
2024-10-14 08:04:33,446 - INFO - Skipping Prompt 10 (myrmecology_timeline): Output already exists.
2024-10-14 08:04:33,447 - INFO - Skipping Prompt 11 (parasite_arms_race): Output already exists.
2024-10-14 08:04:33,447 - INFO - Skipping Prompt 12 (urbanization_effects): Output already exists.
2024-10-14 08:04:33,447 - INFO - Skipping Prompt 13 (pharmaceutical_potential): Output already exists.
2024-10-14 08:04:33,447 - INFO - Skipping Prompt 14 (epigenetics_caste_determination): Output already exists.
2024-10-14 08:04:33,447 - INFO - Skipping Prompt 15 (tropical_ecosystem_interactions): Output already exists.
2024-10-14 08:04:33,448 - INFO - Skipping Prompt 16 (phylogenomic_analysis): Output already exists.
2024-10-14 08:04:33,448 - INFO - Skipping Prompt 17 (emerging_tech_impact): Output already exists.
2024-10-14 08:04:33,448 - INFO - Skipping Prompt 18 (conservation_assessment): Output already exists.
2024-10-14 08:04:33,448 - INFO - Skipping Prompt 19 (bioindicator_role): Output already exists.
2024-10-14 08:04:33,448 - INFO - Skipping Prompt 20 (swarm_intelligence_applications): Output already exists.
2024-10-14 08:04:33,449 - INFO - Skipping Prompt 21 (biogenic_amines_foraging): Output already exists.
2024-10-14 08:04:33,449 - INFO - Skipping Prompt 22 (brain_regions_foraging): Output already exists.
2024-10-14 08:04:33,449 - INFO - Skipping Prompt 23 (neural_variability_foraging): Output already exists.
2024-10-14 08:04:33,449 - INFO - Skipping Prompt 24 (deborah_gordon_meta_analysis): Output already exists.
2024-10-14 08:04:33,449 - INFO - Skipping Prompt 25 (tim_linksvayer_meta_analysis): Output already exists.
2024-10-14 08:04:33,450 - INFO - Skipping Prompt 26 (colony_behavior_relatedness): Output already exists.
2024-10-14 08:04:33,450 - INFO - Skipping Prompt 27 (nestmate_morphology_relatedness): Output already exists.
2024-10-14 08:04:33,450 - INFO - Skipping Prompt 28 (colony_behavior_genetic_correlation): Output already exists.
2024-10-14 08:04:33,450 - INFO - Skipping Prompt 29 (nestmate_behavior_relatedness): Output already exists.
2024-10-14 08:04:33,450 - INFO - Skipping Prompt 30 (colony_morphology_relatedness): Output already exists.
2024-10-14 08:04:33,451 - INFO - Skipping Prompt 31 (colony_behavior_morphology_relatedness): Output already exists.
2024-10-14 08:04:33,451 - INFO - Skipping Prompt 32 (nestmate_trait_relatedness_meta_analysis): Output already exists.
2024-10-14 08:04:33,451 - INFO - Skipping Prompt 33 (camponotus_recent_research): Output already exists.
2024-10-14 08:04:33,451 - INFO - Skipping Prompt 34 (formica_recent_studies): Output already exists.
2024-10-14 08:04:33,451 - INFO - Skipping Prompt 35 (pheidole_diversity_ecology): Output already exists.
2024-10-14 08:04:33,452 - INFO - Skipping Prompt 36 (atta_leafcutter_research): Output already exists.
2024-10-14 08:04:33,452 - INFO - Skipping Prompt 37 (solenopsis_fire_ant_studies): Output already exists.
2024-10-14 08:04:33,452 - INFO - Skipping Prompt 38 (monomorium_global_research): Output already exists.
2024-10-14 08:04:33,452 - INFO - Skipping Prompt 39 (lasius_ecosystem_interactions): Output already exists.
2024-10-14 08:04:33,452 - INFO - Skipping Prompt 40 (oecophylla_weaver_ant_research): Output already exists.
2024-10-14 08:04:33,453 - INFO - Skipping Prompt 41 (pogonomyrmex_barbatus_research): Output already exists.
2024-10-14 08:04:33,453 - INFO - Skipping Prompt 42 (non_barbatus_pogonomyrmex_studies): Output already exists.
2024-10-14 08:04:33,453 - INFO - Processing Prompt 43: Analyze recent research (2020-2024) on the impact ...
2024-10-14 08:04:33,819 - INFO - Retrying request to /chat/completions in 0.853557 seconds
2024-10-14 08:04:34,824 - INFO - Retrying request to /chat/completions in 1.788752 seconds
2024-10-14 08:04:37,228 - ERROR - Unexpected error processing Prompt 43: Connection error.
Traceback (most recent call last):
  File "/usr/lib/python3/dist-packages/httpcore/_exceptions.py", line 10, in map_exceptions
    yield
  File "/usr/lib/python3/dist-packages/httpcore/_sync/http11.py", line 121, in _send_request_headers
    event = h11.Request(
            ^^^^^^^^^^^^
  File "/usr/lib/python3/dist-packages/h11/_events.py", line 96, in __init__
    self, "headers", normalize_and_validate(headers, _parsed=_parsed)
                     ^^^^^^^^^^^^^^^^^^^^^^^^^^^^^^^^^^^^^^^^^^^^^^^^
  File "/usr/lib/python3/dist-packages/h11/_headers.py", line 164, in normalize_and_validate
    validate(_field_value_re, value, "Illegal header value {!r}", value)
  File "/usr/lib/python3/dist-packages/h11/_util.py", line 91, in validate
    raise LocalProtocolError(msg)
h11._util.LocalProtocolError: Illegal header value b'Bearer OPENAI_API_KEY=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\nPERPLEXITY_API_KEY=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'

During handling of the above exception, another exception occurred:

Traceback (most recent call last):
  File "/usr/lib/python3/dist-packages/httpx/_transports/default.py", line 60, in map_httpcore_exceptions
    yield
  File "/usr/lib/python3/dist-packages/httpx/_transports/default.py", line 218, in handle_request
    resp = self._pool.handle_request(req)
           ^^^^^^^^^^^^^^^^^^^^^^^^^^^^^^
  File "/usr/lib/python3/dist-packages/httpcore/_sync/connection_pool.py", line 253, in handle_request
    raise exc
  File "/usr/lib/python3/dist-packages/httpcore/_sync/connection_pool.py", line 237, in handle_request
    response = connection.handle_request(request)
               ^^^^^^^^^^^^^^^^^^^^^^^^^^^^^^^^^^
  File "/usr/lib/python3/dist-packages/httpcore/_sync/connection.py", line 90, in handle_request
    return self._connection.handle_request(request)
           ^^^^^^^^^^^^^^^^^^^^^^^^^^^^^^^^^^^^^^^^
  File "/usr/lib/python3/dist-packages/httpcore/_sync/http11.py", line 112, in handle_request
    raise exc
  File "/usr/lib/python3/dist-packages/httpcore/_sync/http11.py", line 80, in handle_request
    self._send_request_headers(**kwargs)
  File "/usr/lib/python3/dist-packages/httpcore/_sync/http11.py", line 120, in _send_request_headers
    with map_exceptions({h11.LocalProtocolError: LocalProtocolError}):
  File "/usr/lib/python3.11/contextlib.py", line 155, in __exit__
    self.gen.throw(typ, value, traceback)
  File "/usr/lib/python3/dist-packages/httpcore/_exceptions.py", line 14, in map_exceptions
    raise to_exc(exc)
httpcore.LocalProtocolError: Illegal header value b'Bearer OPENAI_API_KEY=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\nPERPLEXITY_API_KEY=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'

The above exception was the direct cause of the following exception:

Traceback (most recent call last):
  File "/home/trim/.local/lib/python3.11/site-packages/openai/_base_client.py", line 972, in _request
    response = self._client.send(
               ^^^^^^^^^^^^^^^^^^
  File "/usr/lib/python3/dist-packages/httpx/_client.py", line 908, in send
    response = self._send_handling_auth(
               ^^^^^^^^^^^^^^^^^^^^^^^^^
  File "/usr/lib/python3/dist-packages/httpx/_client.py", line 936, in _send_handling_auth
    response = self._send_handling_redirects(
               ^^^^^^^^^^^^^^^^^^^^^^^^^^^^^^
  File "/usr/lib/python3/dist-packages/httpx/_client.py", line 973, in _send_handling_redirects
    response = self._send_single_request(request)
               ^^^^^^^^^^^^^^^^^^^^^^^^^^^^^^^^^^
  File "/usr/lib/python3/dist-packages/httpx/_client.py", line 1009, in _send_single_request
    response = transport.handle_request(request)
               ^^^^^^^^^^^^^^^^^^^^^^^^^^^^^^^^^
  File "/usr/lib/python3/dist-packages/httpx/_transports/default.py", line 217, in handle_request
    with map_httpcore_exceptions():
  File "/usr/lib/python3.11/contextlib.py", line 155, in __exit__
    self.gen.throw(typ, value, traceback)
  File "/usr/lib/python3/dist-packages/httpx/_transports/default.py", line 77, in map_httpcore_exceptions
    raise mapped_exc(message) from exc
httpx.LocalProtocolError: Illegal header value b'Bearer OPENAI_API_KEY=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\nPERPLEXITY_API_KEY=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'

During handling of the above exception, another exception occurred:

Traceback (most recent call last):
  File "/usr/lib/python3/dist-packages/httpcore/_exceptions.py", line 10, in map_exceptions
    yield
  File "/usr/lib/python3/dist-packages/httpcore/_sync/http11.py", line 121, in _send_request_headers
    event = h11.Request(
            ^^^^^^^^^^^^
  File "/usr/lib/python3/dist-packages/h11/_events.py", line 96, in __init__
    self, "headers", normalize_and_validate(headers, _parsed=_parsed)
                     ^^^^^^^^^^^^^^^^^^^^^^^^^^^^^^^^^^^^^^^^^^^^^^^^
  File "/usr/lib/python3/dist-packages/h11/_headers.py", line 164, in normalize_and_validate
    validate(_field_value_re, value, "Illegal header value {!r}", value)
  File "/usr/lib/python3/dist-packages/h11/_util.py", line 91, in validate
    raise LocalProtocolError(msg)
h11._util.LocalProtocolError: Illegal header value b'Bearer OPENAI_API_KEY=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\nPERPLEXITY_API_KEY=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'

During handling of the above exception, another exception occurred:

Traceback (most recent call last):
  File "/usr/lib/python3/dist-packages/httpx/_transports/default.py", line 60, in map_httpcore_exceptions
    yield
  File "/usr/lib/python3/dist-packages/httpx/_transports/default.py", line 218, in handle_request
    resp = self._pool.handle_request(req)
           ^^^^^^^^^^^^^^^^^^^^^^^^^^^^^^
  File "/usr/lib/python3/dist-packages/httpcore/_sync/connection_pool.py", line 253, in handle_request
    raise exc
  File "/usr/lib/python3/dist-packages/httpcore/_sync/connection_pool.py", line 237, in handle_request
    response = connection.handle_request(request)
               ^^^^^^^^^^^^^^^^^^^^^^^^^^^^^^^^^^
  File "/usr/lib/python3/dist-packages/httpcore/_sync/connection.py", line 90, in handle_request
    return self._connection.handle_request(request)
           ^^^^^^^^^^^^^^^^^^^^^^^^^^^^^^^^^^^^^^^^
  File "/usr/lib/python3/dist-packages/httpcore/_sync/http11.py", line 112, in handle_request
    raise exc
  File "/usr/lib/python3/dist-packages/httpcore/_sync/http11.py", line 80, in handle_request
    self._send_request_headers(**kwargs)
  File "/usr/lib/python3/dist-packages/httpcore/_sync/http11.py", line 120, in _send_request_headers
    with map_exceptions({h11.LocalProtocolError: LocalProtocolError}):
  File "/usr/lib/python3.11/contextlib.py", line 155, in __exit__
    self.gen.throw(typ, value, traceback)
  File "/usr/lib/python3/dist-packages/httpcore/_exceptions.py", line 14, in map_exceptions
    raise to_exc(exc)
httpcore.LocalProtocolError: Illegal header value b'Bearer OPENAI_API_KEY=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\nPERPLEXITY_API_KEY=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'

The above exception was the direct cause of the following exception:

Traceback (most recent call last):
  File "/home/trim/.local/lib/python3.11/site-packages/openai/_base_client.py", line 972, in _request
    response = self._client.send(
               ^^^^^^^^^^^^^^^^^^
  File "/usr/lib/python3/dist-packages/httpx/_client.py", line 908, in send
    response = self._send_handling_auth(
               ^^^^^^^^^^^^^^^^^^^^^^^^^
  File "/usr/lib/python3/dist-packages/httpx/_client.py", line 936, in _send_handling_auth
    response = self._send_handling_redirects(
               ^^^^^^^^^^^^^^^^^^^^^^^^^^^^^^
  File "/usr/lib/python3/dist-packages/httpx/_client.py", line 973, in _send_handling_redirects
    response = self._send_single_request(request)
               ^^^^^^^^^^^^^^^^^^^^^^^^^^^^^^^^^^
  File "/usr/lib/python3/dist-packages/httpx/_client.py", line 1009, in _send_single_request
    response = transport.handle_request(request)
               ^^^^^^^^^^^^^^^^^^^^^^^^^^^^^^^^^
  File "/usr/lib/python3/dist-packages/httpx/_transports/default.py", line 217, in handle_request
    with map_httpcore_exceptions():
  File "/usr/lib/python3.11/contextlib.py", line 155, in __exit__
    self.gen.throw(typ, value, traceback)
  File "/usr/lib/python3/dist-packages/httpx/_transports/default.py", line 77, in map_httpcore_exceptions
    raise mapped_exc(message) from exc
httpx.LocalProtocolError: Illegal header value b'Bearer OPENAI_API_KEY=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\nPERPLEXITY_API_KEY=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'

During handling of the above exception, another exception occurred:

Traceback (most recent call last):
  File "/usr/lib/python3/dist-packages/httpcore/_exceptions.py", line 10, in map_exceptions
    yield
  File "/usr/lib/python3/dist-packages/httpcore/_sync/http11.py", line 121, in _send_request_headers
    event = h11.Request(
            ^^^^^^^^^^^^
  File "/usr/lib/python3/dist-packages/h11/_events.py", line 96, in __init__
    self, "headers", normalize_and_validate(headers, _parsed=_parsed)
                     ^^^^^^^^^^^^^^^^^^^^^^^^^^^^^^^^^^^^^^^^^^^^^^^^
  File "/usr/lib/python3/dist-packages/h11/_headers.py", line 164, in normalize_and_validate
    validate(_field_value_re, value, "Illegal header value {!r}", value)
  File "/usr/lib/python3/dist-packages/h11/_util.py", line 91, in validate
    raise LocalProtocolError(msg)
h11._util.LocalProtocolError: Illegal header value b'Bearer OPENAI_API_KEY=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\nPERPLEXITY_API_KEY=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'

During handling of the above exception, another exception occurred:

Traceback (most recent call last):
  File "/usr/lib/python3/dist-packages/httpx/_transports/default.py", line 60, in map_httpcore_exceptions
    yield
  File "/usr/lib/python3/dist-packages/httpx/_transports/default.py", line 218, in handle_request
    resp = self._pool.handle_request(req)
           ^^^^^^^^^^^^^^^^^^^^^^^^^^^^^^
  File "/usr/lib/python3/dist-packages/httpcore/_sync/connection_pool.py", line 253, in handle_request
    raise exc
  File "/usr/lib/python3/dist-packages/httpcore/_sync/connection_pool.py", line 237, in handle_request
    response = connection.handle_request(request)
               ^^^^^^^^^^^^^^^^^^^^^^^^^^^^^^^^^^
  File "/usr/lib/python3/dist-packages/httpcore/_sync/connection.py", line 90, in handle_request
    return self._connection.handle_request(request)
           ^^^^^^^^^^^^^^^^^^^^^^^^^^^^^^^^^^^^^^^^
  File "/usr/lib/python3/dist-packages/httpcore/_sync/http11.py", line 112, in handle_request
    raise exc
  File "/usr/lib/python3/dist-packages/httpcore/_sync/http11.py", line 80, in handle_request
    self._send_request_headers(**kwargs)
  File "/usr/lib/python3/dist-packages/httpcore/_sync/http11.py", line 120, in _send_request_headers
    with map_exceptions({h11.LocalProtocolError: LocalProtocolError}):
  File "/usr/lib/python3.11/contextlib.py", line 155, in __exit__
    self.gen.throw(typ, value, traceback)
  File "/usr/lib/python3/dist-packages/httpcore/_exceptions.py", line 14, in map_exceptions
    raise to_exc(exc)
httpcore.LocalProtocolError: Illegal header value b'Bearer OPENAI_API_KEY=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\nPERPLEXITY_API_KEY=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'

The above exception was the direct cause of the following exception:

Traceback (most recent call last):
  File "/home/trim/.local/lib/python3.11/site-packages/openai/_base_client.py", line 972, in _request
    response = self._client.send(
               ^^^^^^^^^^^^^^^^^^
  File "/usr/lib/python3/dist-packages/httpx/_client.py", line 908, in send
    response = self._send_handling_auth(
               ^^^^^^^^^^^^^^^^^^^^^^^^^
  File "/usr/lib/python3/dist-packages/httpx/_client.py", line 936, in _send_handling_auth
    response = self._send_handling_redirects(
               ^^^^^^^^^^^^^^^^^^^^^^^^^^^^^^
  File "/usr/lib/python3/dist-packages/httpx/_client.py", line 973, in _send_handling_redirects
    response = self._send_single_request(request)
               ^^^^^^^^^^^^^^^^^^^^^^^^^^^^^^^^^^
  File "/usr/lib/python3/dist-packages/httpx/_client.py", line 1009, in _send_single_request
    response = transport.handle_request(request)
               ^^^^^^^^^^^^^^^^^^^^^^^^^^^^^^^^^
  File "/usr/lib/python3/dist-packages/httpx/_transports/default.py", line 217, in handle_request
    with map_httpcore_exceptions():
  File "/usr/lib/python3.11/contextlib.py", line 155, in __exit__
    self.gen.throw(typ, value, traceback)
  File "/usr/lib/python3/dist-packages/httpx/_transports/default.py", line 77, in map_httpcore_exceptions
    raise mapped_exc(message) from exc
httpx.LocalProtocolError: Illegal header value b'Bearer OPENAI_API_KEY=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\nPERPLEXITY_API_KEY=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'

The above exception was the direct cause of the following exception:

Traceback (most recent call last):
  File "/home/trim/Documents/GitHub/FORMINDEX/Perplexity_Methods/Perplexity.py", line 122, in <module>
    response = client.chat.completions.create(
               ^^^^^^^^^^^^^^^^^^^^^^^^^^^^^^^
  File "/home/trim/.local/lib/python3.11/site-packages/openai/_utils/_utils.py", line 274, in wrapper
    return func(*args, **kwargs)
           ^^^^^^^^^^^^^^^^^^^^^
  File "/home/trim/.local/lib/python3.11/site-packages/openai/resources/chat/completions.py", line 668, in create
    return self._post(
           ^^^^^^^^^^^
  File "/home/trim/.local/lib/python3.11/site-packages/openai/_base_client.py", line 1259, in post
    return cast(ResponseT, self.request(cast_to, opts, stream=stream, stream_cls=stream_cls))
                           ^^^^^^^^^^^^^^^^^^^^^^^^^^^^^^^^^^^^^^^^^^^^^^^^^^^^^^^^^^^^^^^^^
  File "/home/trim/.local/lib/python3.11/site-packages/openai/_base_client.py", line 936, in request
    return self._request(
           ^^^^^^^^^^^^^^
  File "/home/trim/.local/lib/python3.11/site-packages/openai/_base_client.py", line 996, in _request
    return self._retry_request(
           ^^^^^^^^^^^^^^^^^^^^
  File "/home/trim/.local/lib/python3.11/site-packages/openai/_base_client.py", line 1074, in _retry_request
    return self._request(
           ^^^^^^^^^^^^^^
  File "/home/trim/.local/lib/python3.11/site-packages/openai/_base_client.py", line 996, in _request
    return self._retry_request(
           ^^^^^^^^^^^^^^^^^^^^
  File "/home/trim/.local/lib/python3.11/site-packages/openai/_base_client.py", line 1074, in _retry_request
    return self._request(
           ^^^^^^^^^^^^^^
  File "/home/trim/.local/lib/python3.11/site-packages/openai/_base_client.py", line 1006, in _request
    raise APIConnectionError(request=request) from err
openai.APIConnectionError: Connection error.
2024-10-14 08:04:40,232 - INFO - Processing Prompt 44: Review recent studies (2020-2024) on the effects o...
2024-10-14 08:04:40,403 - INFO - Retrying request to /chat/completions in 0.880705 seconds
2024-10-14 08:16:14,717 - INFO - API Key: OPENAI_API_KEY=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
PERPLEXITY_API_KEY=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
2024-10-14 08:16:14,741 - INFO - Skipping Prompt 1 (climate_change_impact): Output already exists.
2024-10-14 08:16:14,741 - INFO - Skipping Prompt 2 (colony_simulation_model): Output already exists.
2024-10-14 08:16:14,741 - INFO - Skipping Prompt 3 (navigation_breakthroughs): Output already exists.
2024-10-14 08:16:14,741 - INFO - Skipping Prompt 4 (invasive_species_economics): Output already exists.
2024-10-14 08:16:14,742 - INFO - Skipping Prompt 5 (crispr_gene_editing): Output already exists.
2024-10-14 08:16:14,742 - INFO - Skipping Prompt 6 (recent_new_species): Output already exists.
2024-10-14 08:16:14,742 - INFO - Skipping Prompt 7 (carbon_cycling_impact): Output already exists.
2024-10-14 08:16:14,742 - INFO - Skipping Prompt 8 (ant_inspired_algorithms): Output already exists.
2024-10-14 08:16:14,742 - INFO - Skipping Prompt 9 (supercolony_formation): Output already exists.
2024-10-14 08:16:14,742 - INFO - Skipping Prompt 10 (myrmecology_timeline): Output already exists.
2024-10-14 08:16:14,743 - INFO - Skipping Prompt 11 (parasite_arms_race): Output already exists.
2024-10-14 08:16:14,743 - INFO - Skipping Prompt 12 (urbanization_effects): Output already exists.
2024-10-14 08:16:14,743 - INFO - Skipping Prompt 13 (pharmaceutical_potential): Output already exists.
2024-10-14 08:16:14,743 - INFO - Skipping Prompt 14 (epigenetics_caste_determination): Output already exists.
2024-10-14 08:16:14,743 - INFO - Skipping Prompt 15 (tropical_ecosystem_interactions): Output already exists.
2024-10-14 08:16:14,744 - INFO - Skipping Prompt 16 (phylogenomic_analysis): Output already exists.
2024-10-14 08:16:14,744 - INFO - Skipping Prompt 17 (emerging_tech_impact): Output already exists.
2024-10-14 08:16:14,744 - INFO - Skipping Prompt 18 (conservation_assessment): Output already exists.
2024-10-14 08:16:14,744 - INFO - Skipping Prompt 19 (bioindicator_role): Output already exists.
2024-10-14 08:16:14,744 - INFO - Skipping Prompt 20 (swarm_intelligence_applications): Output already exists.
2024-10-14 08:16:14,744 - INFO - Skipping Prompt 21 (biogenic_amines_foraging): Output already exists.
2024-10-14 08:16:14,745 - INFO - Skipping Prompt 22 (brain_regions_foraging): Output already exists.
2024-10-14 08:16:14,745 - INFO - Skipping Prompt 23 (neural_variability_foraging): Output already exists.
2024-10-14 08:16:14,745 - INFO - Skipping Prompt 24 (deborah_gordon_meta_analysis): Output already exists.
2024-10-14 08:16:14,745 - INFO - Skipping Prompt 25 (tim_linksvayer_meta_analysis): Output already exists.
2024-10-14 08:16:14,745 - INFO - Skipping Prompt 26 (colony_behavior_relatedness): Output already exists.
2024-10-14 08:16:14,746 - INFO - Skipping Prompt 27 (nestmate_morphology_relatedness): Output already exists.
2024-10-14 08:16:14,746 - INFO - Skipping Prompt 28 (colony_behavior_genetic_correlation): Output already exists.
2024-10-14 08:16:14,746 - INFO - Skipping Prompt 29 (nestmate_behavior_relatedness): Output already exists.
2024-10-14 08:16:14,746 - INFO - Skipping Prompt 30 (colony_morphology_relatedness): Output already exists.
2024-10-14 08:16:14,746 - INFO - Skipping Prompt 31 (colony_behavior_morphology_relatedness): Output already exists.
2024-10-14 08:16:14,746 - INFO - Skipping Prompt 32 (nestmate_trait_relatedness_meta_analysis): Output already exists.
2024-10-14 08:16:14,747 - INFO - Skipping Prompt 33 (camponotus_recent_research): Output already exists.
2024-10-14 08:16:14,747 - INFO - Skipping Prompt 34 (formica_recent_studies): Output already exists.
2024-10-14 08:16:14,747 - INFO - Skipping Prompt 35 (pheidole_diversity_ecology): Output already exists.
2024-10-14 08:16:14,747 - INFO - Skipping Prompt 36 (atta_leafcutter_research): Output already exists.
2024-10-14 08:16:14,747 - INFO - Skipping Prompt 37 (solenopsis_fire_ant_studies): Output already exists.
2024-10-14 08:16:14,747 - INFO - Skipping Prompt 38 (monomorium_global_research): Output already exists.
2024-10-14 08:16:14,747 - INFO - Skipping Prompt 39 (lasius_ecosystem_interactions): Output already exists.
2024-10-14 08:16:14,748 - INFO - Skipping Prompt 40 (oecophylla_weaver_ant_research): Output already exists.
2024-10-14 08:16:14,748 - INFO - Skipping Prompt 41 (pogonomyrmex_barbatus_research): Output already exists.
2024-10-14 08:16:14,748 - INFO - Skipping Prompt 42 (non_barbatus_pogonomyrmex_studies): Output already exists.
2024-10-14 08:16:14,748 - INFO - Processing Prompt 43: Analyze recent research (2020-2024) on the impact ...
2024-10-14 08:16:14,908 - INFO - Retrying request to /chat/completions in 0.959189 seconds
2024-10-14 08:16:16,212 - INFO - Retrying request to /chat/completions in 1.926922 seconds
2024-10-14 08:16:18,276 - ERROR - Unexpected error processing Prompt 43: Connection error.
Traceback (most recent call last):
  File "/usr/lib/python3/dist-packages/httpcore/_exceptions.py", line 10, in map_exceptions
    yield
  File "/usr/lib/python3/dist-packages/httpcore/_sync/http11.py", line 121, in _send_request_headers
    event = h11.Request(
            ^^^^^^^^^^^^
  File "/usr/lib/python3/dist-packages/h11/_events.py", line 96, in __init__
    self, "headers", normalize_and_validate(headers, _parsed=_parsed)
                     ^^^^^^^^^^^^^^^^^^^^^^^^^^^^^^^^^^^^^^^^^^^^^^^^
  File "/usr/lib/python3/dist-packages/h11/_headers.py", line 164, in normalize_and_validate
    validate(_field_value_re, value, "Illegal header value {!r}", value)
  File "/usr/lib/python3/dist-packages/h11/_util.py", line 91, in validate
    raise LocalProtocolError(msg)
h11._util.LocalProtocolError: Illegal header value b'Bearer OPENAI_API_KEY=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\nPERPLEXITY_API_KEY=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'

During handling of the above exception, another exception occurred:

Traceback (most recent call last):
  File "/usr/lib/python3/dist-packages/httpx/_transports/default.py", line 60, in map_httpcore_exceptions
    yield
  File "/usr/lib/python3/dist-packages/httpx/_transports/default.py", line 218, in handle_request
    resp = self._pool.handle_request(req)
           ^^^^^^^^^^^^^^^^^^^^^^^^^^^^^^
  File "/usr/lib/python3/dist-packages/httpcore/_sync/connection_pool.py", line 253, in handle_request
    raise exc
  File "/usr/lib/python3/dist-packages/httpcore/_sync/connection_pool.py", line 237, in handle_request
    response = connection.handle_request(request)
               ^^^^^^^^^^^^^^^^^^^^^^^^^^^^^^^^^^
  File "/usr/lib/python3/dist-packages/httpcore/_sync/connection.py", line 90, in handle_request
    return self._connection.handle_request(request)
           ^^^^^^^^^^^^^^^^^^^^^^^^^^^^^^^^^^^^^^^^
  File "/usr/lib/python3/dist-packages/httpcore/_sync/http11.py", line 112, in handle_request
    raise exc
  File "/usr/lib/python3/dist-packages/httpcore/_sync/http11.py", line 80, in handle_request
    self._send_request_headers(**kwargs)
  File "/usr/lib/python3/dist-packages/httpcore/_sync/http11.py", line 120, in _send_request_headers
    with map_exceptions({h11.LocalProtocolError: LocalProtocolError}):
  File "/usr/lib/python3.11/contextlib.py", line 155, in __exit__
    self.gen.throw(typ, value, traceback)
  File "/usr/lib/python3/dist-packages/httpcore/_exceptions.py", line 14, in map_exceptions
    raise to_exc(exc)
httpcore.LocalProtocolError: Illegal header value b'Bearer OPENAI_API_KEY=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\nPERPLEXITY_API_KEY=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'

The above exception was the direct cause of the following exception:

Traceback (most recent call last):
  File "/home/trim/.local/lib/python3.11/site-packages/openai/_base_client.py", line 972, in _request
    response = self._client.send(
               ^^^^^^^^^^^^^^^^^^
  File "/usr/lib/python3/dist-packages/httpx/_client.py", line 908, in send
    response = self._send_handling_auth(
               ^^^^^^^^^^^^^^^^^^^^^^^^^
  File "/usr/lib/python3/dist-packages/httpx/_client.py", line 936, in _send_handling_auth
    response = self._send_handling_redirects(
               ^^^^^^^^^^^^^^^^^^^^^^^^^^^^^^
  File "/usr/lib/python3/dist-packages/httpx/_client.py", line 973, in _send_handling_redirects
    response = self._send_single_request(request)
               ^^^^^^^^^^^^^^^^^^^^^^^^^^^^^^^^^^
  File "/usr/lib/python3/dist-packages/httpx/_client.py", line 1009, in _send_single_request
    response = transport.handle_request(request)
               ^^^^^^^^^^^^^^^^^^^^^^^^^^^^^^^^^
  File "/usr/lib/python3/dist-packages/httpx/_transports/default.py", line 217, in handle_request
    with map_httpcore_exceptions():
  File "/usr/lib/python3.11/contextlib.py", line 155, in __exit__
    self.gen.throw(typ, value, traceback)
  File "/usr/lib/python3/dist-packages/httpx/_transports/default.py", line 77, in map_httpcore_exceptions
    raise mapped_exc(message) from exc
httpx.LocalProtocolError: Illegal header value b'Bearer OPENAI_API_KEY=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\nPERPLEXITY_API_KEY=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'

During handling of the above exception, another exception occurred:

Traceback (most recent call last):
  File "/usr/lib/python3/dist-packages/httpcore/_exceptions.py", line 10, in map_exceptions
    yield
  File "/usr/lib/python3/dist-packages/httpcore/_sync/http11.py", line 121, in _send_request_headers
    event = h11.Request(
            ^^^^^^^^^^^^
  File "/usr/lib/python3/dist-packages/h11/_events.py", line 96, in __init__
    self, "headers", normalize_and_validate(headers, _parsed=_parsed)
                     ^^^^^^^^^^^^^^^^^^^^^^^^^^^^^^^^^^^^^^^^^^^^^^^^
  File "/usr/lib/python3/dist-packages/h11/_headers.py", line 164, in normalize_and_validate
    validate(_field_value_re, value, "Illegal header value {!r}", value)
  File "/usr/lib/python3/dist-packages/h11/_util.py", line 91, in validate
    raise LocalProtocolError(msg)
h11._util.LocalProtocolError: Illegal header value b'Bearer OPENAI_API_KEY=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\nPERPLEXITY_API_KEY=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'

During handling of the above exception, another exception occurred:

Traceback (most recent call last):
  File "/usr/lib/python3/dist-packages/httpx/_transports/default.py", line 60, in map_httpcore_exceptions
    yield
  File "/usr/lib/python3/dist-packages/httpx/_transports/default.py", line 218, in handle_request
    resp = self._pool.handle_request(req)
           ^^^^^^^^^^^^^^^^^^^^^^^^^^^^^^
  File "/usr/lib/python3/dist-packages/httpcore/_sync/connection_pool.py", line 253, in handle_request
    raise exc
  File "/usr/lib/python3/dist-packages/httpcore/_sync/connection_pool.py", line 237, in handle_request
    response = connection.handle_request(request)
               ^^^^^^^^^^^^^^^^^^^^^^^^^^^^^^^^^^
  File "/usr/lib/python3/dist-packages/httpcore/_sync/connection.py", line 90, in handle_request
    return self._connection.handle_request(request)
           ^^^^^^^^^^^^^^^^^^^^^^^^^^^^^^^^^^^^^^^^
  File "/usr/lib/python3/dist-packages/httpcore/_sync/http11.py", line 112, in handle_request
    raise exc
  File "/usr/lib/python3/dist-packages/httpcore/_sync/http11.py", line 80, in handle_request
    self._send_request_headers(**kwargs)
  File "/usr/lib/python3/dist-packages/httpcore/_sync/http11.py", line 120, in _send_request_headers
    with map_exceptions({h11.LocalProtocolError: LocalProtocolError}):
  File "/usr/lib/python3.11/contextlib.py", line 155, in __exit__
    self.gen.throw(typ, value, traceback)
  File "/usr/lib/python3/dist-packages/httpcore/_exceptions.py", line 14, in map_exceptions
    raise to_exc(exc)
httpcore.LocalProtocolError: Illegal header value b'Bearer OPENAI_API_KEY=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\nPERPLEXITY_API_KEY=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'

The above exception was the direct cause of the following exception:

Traceback (most recent call last):
  File "/home/trim/.local/lib/python3.11/site-packages/openai/_base_client.py", line 972, in _request
    response = self._client.send(
               ^^^^^^^^^^^^^^^^^^
  File "/usr/lib/python3/dist-packages/httpx/_client.py", line 908, in send
    response = self._send_handling_auth(
               ^^^^^^^^^^^^^^^^^^^^^^^^^
  File "/usr/lib/python3/dist-packages/httpx/_client.py", line 936, in _send_handling_auth
    response = self._send_handling_redirects(
               ^^^^^^^^^^^^^^^^^^^^^^^^^^^^^^
  File "/usr/lib/python3/dist-packages/httpx/_client.py", line 973, in _send_handling_redirects
    response = self._send_single_request(request)
               ^^^^^^^^^^^^^^^^^^^^^^^^^^^^^^^^^^
  File "/usr/lib/python3/dist-packages/httpx/_client.py", line 1009, in _send_single_request
    response = transport.handle_request(request)
               ^^^^^^^^^^^^^^^^^^^^^^^^^^^^^^^^^
  File "/usr/lib/python3/dist-packages/httpx/_transports/default.py", line 217, in handle_request
    with map_httpcore_exceptions():
  File "/usr/lib/python3.11/contextlib.py", line 155, in __exit__
    self.gen.throw(typ, value, traceback)
  File "/usr/lib/python3/dist-packages/httpx/_transports/default.py", line 77, in map_httpcore_exceptions
    raise mapped_exc(message) from exc
httpx.LocalProtocolError: Illegal header value b'Bearer OPENAI_API_KEY=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\nPERPLEXITY_API_KEY=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'

During handling of the above exception, another exception occurred:

Traceback (most recent call last):
  File "/usr/lib/python3/dist-packages/httpcore/_exceptions.py", line 10, in map_exceptions
    yield
  File "/usr/lib/python3/dist-packages/httpcore/_sync/http11.py", line 121, in _send_request_headers
    event = h11.Request(
            ^^^^^^^^^^^^
  File "/usr/lib/python3/dist-packages/h11/_events.py", line 96, in __init__
    self, "headers", normalize_and_validate(headers, _parsed=_parsed)
                     ^^^^^^^^^^^^^^^^^^^^^^^^^^^^^^^^^^^^^^^^^^^^^^^^
  File "/usr/lib/python3/dist-packages/h11/_headers.py", line 164, in normalize_and_validate
    validate(_field_value_re, value, "Illegal header value {!r}", value)
  File "/usr/lib/python3/dist-packages/h11/_util.py", line 91, in validate
    raise LocalProtocolError(msg)
h11._util.LocalProtocolError: Illegal header value b'Bearer OPENAI_API_KEY=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\nPERPLEXITY_API_KEY=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'

During handling of the above exception, another exception occurred:

Traceback (most recent call last):
  File "/usr/lib/python3/dist-packages/httpx/_transports/default.py", line 60, in map_httpcore_exceptions
    yield
  File "/usr/lib/python3/dist-packages/httpx/_transports/default.py", line 218, in handle_request
    resp = self._pool.handle_request(req)
           ^^^^^^^^^^^^^^^^^^^^^^^^^^^^^^
  File "/usr/lib/python3/dist-packages/httpcore/_sync/connection_pool.py", line 253, in handle_request
    raise exc
  File "/usr/lib/python3/dist-packages/httpcore/_sync/connection_pool.py", line 237, in handle_request
    response = connection.handle_request(request)
               ^^^^^^^^^^^^^^^^^^^^^^^^^^^^^^^^^^
  File "/usr/lib/python3/dist-packages/httpcore/_sync/connection.py", line 90, in handle_request
    return self._connection.handle_request(request)
           ^^^^^^^^^^^^^^^^^^^^^^^^^^^^^^^^^^^^^^^^
  File "/usr/lib/python3/dist-packages/httpcore/_sync/http11.py", line 112, in handle_request
    raise exc
  File "/usr/lib/python3/dist-packages/httpcore/_sync/http11.py", line 80, in handle_request
    self._send_request_headers(**kwargs)
  File "/usr/lib/python3/dist-packages/httpcore/_sync/http11.py", line 120, in _send_request_headers
    with map_exceptions({h11.LocalProtocolError: LocalProtocolError}):
  File "/usr/lib/python3.11/contextlib.py", line 155, in __exit__
    self.gen.throw(typ, value, traceback)
  File "/usr/lib/python3/dist-packages/httpcore/_exceptions.py", line 14, in map_exceptions
    raise to_exc(exc)
httpcore.LocalProtocolError: Illegal header value b'Bearer OPENAI_API_KEY=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\nPERPLEXITY_API_KEY=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'

The above exception was the direct cause of the following exception:

Traceback (most recent call last):
  File "/home/trim/.local/lib/python3.11/site-packages/openai/_base_client.py", line 972, in _request
    response = self._client.send(
               ^^^^^^^^^^^^^^^^^^
  File "/usr/lib/python3/dist-packages/httpx/_client.py", line 908, in send
    response = self._send_handling_auth(
               ^^^^^^^^^^^^^^^^^^^^^^^^^
  File "/usr/lib/python3/dist-packages/httpx/_client.py", line 936, in _send_handling_auth
    response = self._send_handling_redirects(
               ^^^^^^^^^^^^^^^^^^^^^^^^^^^^^^
  File "/usr/lib/python3/dist-packages/httpx/_client.py", line 973, in _send_handling_redirects
    response = self._send_single_request(request)
               ^^^^^^^^^^^^^^^^^^^^^^^^^^^^^^^^^^
  File "/usr/lib/python3/dist-packages/httpx/_client.py", line 1009, in _send_single_request
    response = transport.handle_request(request)
               ^^^^^^^^^^^^^^^^^^^^^^^^^^^^^^^^^
  File "/usr/lib/python3/dist-packages/httpx/_transports/default.py", line 217, in handle_request
    with map_httpcore_exceptions():
  File "/usr/lib/python3.11/contextlib.py", line 155, in __exit__
    self.gen.throw(typ, value, traceback)
  File "/usr/lib/python3/dist-packages/httpx/_transports/default.py", line 77, in map_httpcore_exceptions
    raise mapped_exc(message) from exc
httpx.LocalProtocolError: Illegal header value b'Bearer OPENAI_API_KEY=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\nPERPLEXITY_API_KEY=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'

The above exception was the direct cause of the following exception:

Traceback (most recent call last):
  File "/home/trim/Documents/GitHub/FORMINDEX/Perplexity_Methods/Perplexity.py", line 122, in <module>
    response = client.chat.completions.create(
               ^^^^^^^^^^^^^^^^^^^^^^^^^^^^^^^
  File "/home/trim/.local/lib/python3.11/site-packages/openai/_utils/_utils.py", line 274, in wrapper
    return func(*args, **kwargs)
           ^^^^^^^^^^^^^^^^^^^^^
  File "/home/trim/.local/lib/python3.11/site-packages/openai/resources/chat/completions.py", line 668, in create
    return self._post(
           ^^^^^^^^^^^
  File "/home/trim/.local/lib/python3.11/site-packages/openai/_base_client.py", line 1259, in post
    return cast(ResponseT, self.request(cast_to, opts, stream=stream, stream_cls=stream_cls))
                           ^^^^^^^^^^^^^^^^^^^^^^^^^^^^^^^^^^^^^^^^^^^^^^^^^^^^^^^^^^^^^^^^^
  File "/home/trim/.local/lib/python3.11/site-packages/openai/_base_client.py", line 936, in request
    return self._request(
           ^^^^^^^^^^^^^^
  File "/home/trim/.local/lib/python3.11/site-packages/openai/_base_client.py", line 996, in _request
    return self._retry_request(
           ^^^^^^^^^^^^^^^^^^^^
  File "/home/trim/.local/lib/python3.11/site-packages/openai/_base_client.py", line 1074, in _retry_request
    return self._request(
           ^^^^^^^^^^^^^^
  File "/home/trim/.local/lib/python3.11/site-packages/openai/_base_client.py", line 996, in _request
    return self._retry_request(
           ^^^^^^^^^^^^^^^^^^^^
  File "/home/trim/.local/lib/python3.11/site-packages/openai/_base_client.py", line 1074, in _retry_request
    return self._request(
           ^^^^^^^^^^^^^^
  File "/home/trim/.local/lib/python3.11/site-packages/openai/_base_client.py", line 1006, in _request
    raise APIConnectionError(request=request) from err
openai.APIConnectionError: Connection error.
2024-10-14 08:16:21,280 - INFO - Processing Prompt 44: Review recent studies (2020-2024) on the effects o...
2024-10-14 08:16:21,509 - INFO - Retrying request to /chat/completions in 0.810436 seconds
2024-10-14 08:16:22,423 - INFO - Retrying request to /chat/completions in 1.602751 seconds
2024-10-14 08:16:24,210 - ERROR - Unexpected error processing Prompt 44: Connection error.
Traceback (most recent call last):
  File "/usr/lib/python3/dist-packages/httpcore/_exceptions.py", line 10, in map_exceptions
    yield
  File "/usr/lib/python3/dist-packages/httpcore/_sync/http11.py", line 121, in _send_request_headers
    event = h11.Request(
            ^^^^^^^^^^^^
  File "/usr/lib/python3/dist-packages/h11/_events.py", line 96, in __init__
    self, "headers", normalize_and_validate(headers, _parsed=_parsed)
                     ^^^^^^^^^^^^^^^^^^^^^^^^^^^^^^^^^^^^^^^^^^^^^^^^
  File "/usr/lib/python3/dist-packages/h11/_headers.py", line 164, in normalize_and_validate
    validate(_field_value_re, value, "Illegal header value {!r}", value)
  File "/usr/lib/python3/dist-packages/h11/_util.py", line 91, in validate
    raise LocalProtocolError(msg)
h11._util.LocalProtocolError: Illegal header value b'Bearer OPENAI_API_KEY=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\nPERPLEXITY_API_KEY=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'

During handling of the above exception, another exception occurred:

Traceback (most recent call last):
  File "/usr/lib/python3/dist-packages/httpx/_transports/default.py", line 60, in map_httpcore_exceptions
    yield
  File "/usr/lib/python3/dist-packages/httpx/_transports/default.py", line 218, in handle_request
    resp = self._pool.handle_request(req)
           ^^^^^^^^^^^^^^^^^^^^^^^^^^^^^^
  File "/usr/lib/python3/dist-packages/httpcore/_sync/connection_pool.py", line 253, in handle_request
    raise exc
  File "/usr/lib/python3/dist-packages/httpcore/_sync/connection_pool.py", line 237, in handle_request
    response = connection.handle_request(request)
               ^^^^^^^^^^^^^^^^^^^^^^^^^^^^^^^^^^
  File "/usr/lib/python3/dist-packages/httpcore/_sync/connection.py", line 90, in handle_request
    return self._connection.handle_request(request)
           ^^^^^^^^^^^^^^^^^^^^^^^^^^^^^^^^^^^^^^^^
  File "/usr/lib/python3/dist-packages/httpcore/_sync/http11.py", line 112, in handle_request
    raise exc
  File "/usr/lib/python3/dist-packages/httpcore/_sync/http11.py", line 80, in handle_request
    self._send_request_headers(**kwargs)
  File "/usr/lib/python3/dist-packages/httpcore/_sync/http11.py", line 120, in _send_request_headers
    with map_exceptions({h11.LocalProtocolError: LocalProtocolError}):
  File "/usr/lib/python3.11/contextlib.py", line 155, in __exit__
    self.gen.throw(typ, value, traceback)
  File "/usr/lib/python3/dist-packages/httpcore/_exceptions.py", line 14, in map_exceptions
    raise to_exc(exc)
httpcore.LocalProtocolError: Illegal header value b'Bearer OPENAI_API_KEY=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\nPERPLEXITY_API_KEY=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'

The above exception was the direct cause of the following exception:

Traceback (most recent call last):
  File "/home/trim/.local/lib/python3.11/site-packages/openai/_base_client.py", line 972, in _request
    response = self._client.send(
               ^^^^^^^^^^^^^^^^^^
  File "/usr/lib/python3/dist-packages/httpx/_client.py", line 908, in send
    response = self._send_handling_auth(
               ^^^^^^^^^^^^^^^^^^^^^^^^^
  File "/usr/lib/python3/dist-packages/httpx/_client.py", line 936, in _send_handling_auth
    response = self._send_handling_redirects(
               ^^^^^^^^^^^^^^^^^^^^^^^^^^^^^^
  File "/usr/lib/python3/dist-packages/httpx/_client.py", line 973, in _send_handling_redirects
    response = self._send_single_request(request)
               ^^^^^^^^^^^^^^^^^^^^^^^^^^^^^^^^^^
  File "/usr/lib/python3/dist-packages/httpx/_client.py", line 1009, in _send_single_request
    response = transport.handle_request(request)
               ^^^^^^^^^^^^^^^^^^^^^^^^^^^^^^^^^
  File "/usr/lib/python3/dist-packages/httpx/_transports/default.py", line 217, in handle_request
    with map_httpcore_exceptions():
  File "/usr/lib/python3.11/contextlib.py", line 155, in __exit__
    self.gen.throw(typ, value, traceback)
  File "/usr/lib/python3/dist-packages/httpx/_transports/default.py", line 77, in map_httpcore_exceptions
    raise mapped_exc(message) from exc
httpx.LocalProtocolError: Illegal header value b'Bearer OPENAI_API_KEY=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\nPERPLEXITY_API_KEY=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'

During handling of the above exception, another exception occurred:

Traceback (most recent call last):
  File "/usr/lib/python3/dist-packages/httpcore/_exceptions.py", line 10, in map_exceptions
    yield
  File "/usr/lib/python3/dist-packages/httpcore/_sync/http11.py", line 121, in _send_request_headers
    event = h11.Request(
            ^^^^^^^^^^^^
  File "/usr/lib/python3/dist-packages/h11/_events.py", line 96, in __init__
    self, "headers", normalize_and_validate(headers, _parsed=_parsed)
                     ^^^^^^^^^^^^^^^^^^^^^^^^^^^^^^^^^^^^^^^^^^^^^^^^
  File "/usr/lib/python3/dist-packages/h11/_headers.py", line 164, in normalize_and_validate
    validate(_field_value_re, value, "Illegal header value {!r}", value)
  File "/usr/lib/python3/dist-packages/h11/_util.py", line 91, in validate
    raise LocalProtocolError(msg)
h11._util.LocalProtocolError: Illegal header value b'Bearer OPENAI_API_KEY=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\nPERPLEXITY_API_KEY=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'

During handling of the above exception, another exception occurred:

Traceback (most recent call last):
  File "/usr/lib/python3/dist-packages/httpx/_transports/default.py", line 60, in map_httpcore_exceptions
    yield
  File "/usr/lib/python3/dist-packages/httpx/_transports/default.py", line 218, in handle_request
    resp = self._pool.handle_request(req)
           ^^^^^^^^^^^^^^^^^^^^^^^^^^^^^^
  File "/usr/lib/python3/dist-packages/httpcore/_sync/connection_pool.py", line 253, in handle_request
    raise exc
  File "/usr/lib/python3/dist-packages/httpcore/_sync/connection_pool.py", line 237, in handle_request
    response = connection.handle_request(request)
               ^^^^^^^^^^^^^^^^^^^^^^^^^^^^^^^^^^
  File "/usr/lib/python3/dist-packages/httpcore/_sync/connection.py", line 90, in handle_request
    return self._connection.handle_request(request)
           ^^^^^^^^^^^^^^^^^^^^^^^^^^^^^^^^^^^^^^^^
  File "/usr/lib/python3/dist-packages/httpcore/_sync/http11.py", line 112, in handle_request
    raise exc
  File "/usr/lib/python3/dist-packages/httpcore/_sync/http11.py", line 80, in handle_request
    self._send_request_headers(**kwargs)
  File "/usr/lib/python3/dist-packages/httpcore/_sync/http11.py", line 120, in _send_request_headers
    with map_exceptions({h11.LocalProtocolError: LocalProtocolError}):
  File "/usr/lib/python3.11/contextlib.py", line 155, in __exit__
    self.gen.throw(typ, value, traceback)
  File "/usr/lib/python3/dist-packages/httpcore/_exceptions.py", line 14, in map_exceptions
    raise to_exc(exc)
httpcore.LocalProtocolError: Illegal header value b'Bearer OPENAI_API_KEY=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\nPERPLEXITY_API_KEY=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'

The above exception was the direct cause of the following exception:

Traceback (most recent call last):
  File "/home/trim/.local/lib/python3.11/site-packages/openai/_base_client.py", line 972, in _request
    response = self._client.send(
               ^^^^^^^^^^^^^^^^^^
  File "/usr/lib/python3/dist-packages/httpx/_client.py", line 908, in send
    response = self._send_handling_auth(
               ^^^^^^^^^^^^^^^^^^^^^^^^^
  File "/usr/lib/python3/dist-packages/httpx/_client.py", line 936, in _send_handling_auth
    response = self._send_handling_redirects(
               ^^^^^^^^^^^^^^^^^^^^^^^^^^^^^^
  File "/usr/lib/python3/dist-packages/httpx/_client.py", line 973, in _send_handling_redirects
    response = self._send_single_request(request)
               ^^^^^^^^^^^^^^^^^^^^^^^^^^^^^^^^^^
  File "/usr/lib/python3/dist-packages/httpx/_client.py", line 1009, in _send_single_request
    response = transport.handle_request(request)
               ^^^^^^^^^^^^^^^^^^^^^^^^^^^^^^^^^
  File "/usr/lib/python3/dist-packages/httpx/_transports/default.py", line 217, in handle_request
    with map_httpcore_exceptions():
  File "/usr/lib/python3.11/contextlib.py", line 155, in __exit__
    self.gen.throw(typ, value, traceback)
  File "/usr/lib/python3/dist-packages/httpx/_transports/default.py", line 77, in map_httpcore_exceptions
    raise mapped_exc(message) from exc
httpx.LocalProtocolError: Illegal header value b'Bearer OPENAI_API_KEY=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\nPERPLEXITY_API_KEY=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'

During handling of the above exception, another exception occurred:

Traceback (most recent call last):
  File "/usr/lib/python3/dist-packages/httpcore/_exceptions.py", line 10, in map_exceptions
    yield
  File "/usr/lib/python3/dist-packages/httpcore/_sync/http11.py", line 121, in _send_request_headers
    event = h11.Request(
            ^^^^^^^^^^^^
  File "/usr/lib/python3/dist-packages/h11/_events.py", line 96, in __init__
    self, "headers", normalize_and_validate(headers, _parsed=_parsed)
                     ^^^^^^^^^^^^^^^^^^^^^^^^^^^^^^^^^^^^^^^^^^^^^^^^
  File "/usr/lib/python3/dist-packages/h11/_headers.py", line 164, in normalize_and_validate
    validate(_field_value_re, value, "Illegal header value {!r}", value)
  File "/usr/lib/python3/dist-packages/h11/_util.py", line 91, in validate
    raise LocalProtocolError(msg)
h11._util.LocalProtocolError: Illegal header value b'Bearer OPENAI_API_KEY=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\nPERPLEXITY_API_KEY=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'

During handling of the above exception, another exception occurred:

Traceback (most recent call last):
  File "/usr/lib/python3/dist-packages/httpx/_transports/default.py", line 60, in map_httpcore_exceptions
    yield
  File "/usr/lib/python3/dist-packages/httpx/_transports/default.py", line 218, in handle_request
    resp = self._pool.handle_request(req)
           ^^^^^^^^^^^^^^^^^^^^^^^^^^^^^^
  File "/usr/lib/python3/dist-packages/httpcore/_sync/connection_pool.py", line 253, in handle_request
    raise exc
  File "/usr/lib/python3/dist-packages/httpcore/_sync/connection_pool.py", line 237, in handle_request
    response = connection.handle_request(request)
               ^^^^^^^^^^^^^^^^^^^^^^^^^^^^^^^^^^
  File "/usr/lib/python3/dist-packages/httpcore/_sync/connection.py", line 90, in handle_request
    return self._connection.handle_request(request)
           ^^^^^^^^^^^^^^^^^^^^^^^^^^^^^^^^^^^^^^^^
  File "/usr/lib/python3/dist-packages/httpcore/_sync/http11.py", line 112, in handle_request
    raise exc
  File "/usr/lib/python3/dist-packages/httpcore/_sync/http11.py", line 80, in handle_request
    self._send_request_headers(**kwargs)
  File "/usr/lib/python3/dist-packages/httpcore/_sync/http11.py", line 120, in _send_request_headers
    with map_exceptions({h11.LocalProtocolError: LocalProtocolError}):
  File "/usr/lib/python3.11/contextlib.py", line 155, in __exit__
    self.gen.throw(typ, value, traceback)
  File "/usr/lib/python3/dist-packages/httpcore/_exceptions.py", line 14, in map_exceptions
    raise to_exc(exc)
httpcore.LocalProtocolError: Illegal header value b'Bearer OPENAI_API_KEY=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\nPERPLEXITY_API_KEY=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'

The above exception was the direct cause of the following exception:

Traceback (most recent call last):
  File "/home/trim/.local/lib/python3.11/site-packages/openai/_base_client.py", line 972, in _request
    response = self._client.send(
               ^^^^^^^^^^^^^^^^^^
  File "/usr/lib/python3/dist-packages/httpx/_client.py", line 908, in send
    response = self._send_handling_auth(
               ^^^^^^^^^^^^^^^^^^^^^^^^^
  File "/usr/lib/python3/dist-packages/httpx/_client.py", line 936, in _send_handling_auth
    response = self._send_handling_redirects(
               ^^^^^^^^^^^^^^^^^^^^^^^^^^^^^^
  File "/usr/lib/python3/dist-packages/httpx/_client.py", line 973, in _send_handling_redirects
    response = self._send_single_request(request)
               ^^^^^^^^^^^^^^^^^^^^^^^^^^^^^^^^^^
  File "/usr/lib/python3/dist-packages/httpx/_client.py", line 1009, in _send_single_request
    response = transport.handle_request(request)
               ^^^^^^^^^^^^^^^^^^^^^^^^^^^^^^^^^
  File "/usr/lib/python3/dist-packages/httpx/_transports/default.py", line 217, in handle_request
    with map_httpcore_exceptions():
  File "/usr/lib/python3.11/contextlib.py", line 155, in __exit__
    self.gen.throw(typ, value, traceback)
  File "/usr/lib/python3/dist-packages/httpx/_transports/default.py", line 77, in map_httpcore_exceptions
    raise mapped_exc(message) from exc
httpx.LocalProtocolError: Illegal header value b'Bearer OPENAI_API_KEY=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\nPERPLEXITY_API_KEY=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'

The above exception was the direct cause of the following exception:

Traceback (most recent call last):
  File "/home/trim/Documents/GitHub/FORMINDEX/Perplexity_Methods/Perplexity.py", line 122, in <module>
    response = client.chat.completions.create(
               ^^^^^^^^^^^^^^^^^^^^^^^^^^^^^^^
  File "/home/trim/.local/lib/python3.11/site-packages/openai/_utils/_utils.py", line 274, in wrapper
    return func(*args, **kwargs)
           ^^^^^^^^^^^^^^^^^^^^^
  File "/home/trim/.local/lib/python3.11/site-packages/openai/resources/chat/completions.py", line 668, in create
    return self._post(
           ^^^^^^^^^^^
  File "/home/trim/.local/lib/python3.11/site-packages/openai/_base_client.py", line 1259, in post
    return cast(ResponseT, self.request(cast_to, opts, stream=stream, stream_cls=stream_cls))
                           ^^^^^^^^^^^^^^^^^^^^^^^^^^^^^^^^^^^^^^^^^^^^^^^^^^^^^^^^^^^^^^^^^
  File "/home/trim/.local/lib/python3.11/site-packages/openai/_base_client.py", line 936, in request
    return self._request(
           ^^^^^^^^^^^^^^
  File "/home/trim/.local/lib/python3.11/site-packages/openai/_base_client.py", line 996, in _request
    return self._retry_request(
           ^^^^^^^^^^^^^^^^^^^^
  File "/home/trim/.local/lib/python3.11/site-packages/openai/_base_client.py", line 1074, in _retry_request
    return self._request(
           ^^^^^^^^^^^^^^
  File "/home/trim/.local/lib/python3.11/site-packages/openai/_base_client.py", line 996, in _request
    return self._retry_request(
           ^^^^^^^^^^^^^^^^^^^^
  File "/home/trim/.local/lib/python3.11/site-packages/openai/_base_client.py", line 1074, in _retry_request
    return self._request(
           ^^^^^^^^^^^^^^
  File "/home/trim/.local/lib/python3.11/site-packages/openai/_base_client.py", line 1006, in _request
    raise APIConnectionError(request=request) from err
openai.APIConnectionError: Connection error.
2024-10-14 08:17:54,128 - INFO - Skipping Prompt 1 (climate_change_impact): Output already exists.
2024-10-14 08:17:54,128 - INFO - Skipping Prompt 2 (colony_simulation_model): Output already exists.
2024-10-14 08:17:54,129 - INFO - Skipping Prompt 3 (navigation_breakthroughs): Output already exists.
2024-10-14 08:17:54,129 - INFO - Skipping Prompt 4 (invasive_species_economics): Output already exists.
2024-10-14 08:17:54,129 - INFO - Skipping Prompt 5 (crispr_gene_editing): Output already exists.
2024-10-14 08:17:54,129 - INFO - Skipping Prompt 6 (recent_new_species): Output already exists.
2024-10-14 08:17:54,129 - INFO - Skipping Prompt 7 (carbon_cycling_impact): Output already exists.
2024-10-14 08:17:54,129 - INFO - Skipping Prompt 8 (ant_inspired_algorithms): Output already exists.
2024-10-14 08:17:54,129 - INFO - Skipping Prompt 9 (supercolony_formation): Output already exists.
2024-10-14 08:17:54,130 - INFO - Skipping Prompt 10 (myrmecology_timeline): Output already exists.
2024-10-14 08:17:54,130 - INFO - Skipping Prompt 11 (parasite_arms_race): Output already exists.
2024-10-14 08:17:54,130 - INFO - Skipping Prompt 12 (urbanization_effects): Output already exists.
2024-10-14 08:17:54,130 - INFO - Skipping Prompt 13 (pharmaceutical_potential): Output already exists.
2024-10-14 08:17:54,130 - INFO - Skipping Prompt 14 (epigenetics_caste_determination): Output already exists.
2024-10-14 08:17:54,130 - INFO - Skipping Prompt 15 (tropical_ecosystem_interactions): Output already exists.
2024-10-14 08:17:54,131 - INFO - Skipping Prompt 16 (phylogenomic_analysis): Output already exists.
2024-10-14 08:17:54,131 - INFO - Skipping Prompt 17 (emerging_tech_impact): Output already exists.
2024-10-14 08:17:54,131 - INFO - Skipping Prompt 18 (conservation_assessment): Output already exists.
2024-10-14 08:17:54,131 - INFO - Skipping Prompt 19 (bioindicator_role): Output already exists.
2024-10-14 08:17:54,131 - INFO - Skipping Prompt 20 (swarm_intelligence_applications): Output already exists.
2024-10-14 08:17:54,131 - INFO - Skipping Prompt 21 (biogenic_amines_foraging): Output already exists.
2024-10-14 08:17:54,131 - INFO - Skipping Prompt 22 (brain_regions_foraging): Output already exists.
2024-10-14 08:17:54,132 - INFO - Skipping Prompt 23 (neural_variability_foraging): Output already exists.
2024-10-14 08:17:54,132 - INFO - Skipping Prompt 24 (deborah_gordon_meta_analysis): Output already exists.
2024-10-14 08:17:54,132 - INFO - Skipping Prompt 25 (tim_linksvayer_meta_analysis): Output already exists.
2024-10-14 08:17:54,132 - INFO - Skipping Prompt 26 (colony_behavior_relatedness): Output already exists.
2024-10-14 08:17:54,132 - INFO - Skipping Prompt 27 (nestmate_morphology_relatedness): Output already exists.
2024-10-14 08:17:54,132 - INFO - Skipping Prompt 28 (colony_behavior_genetic_correlation): Output already exists.
2024-10-14 08:17:54,132 - INFO - Skipping Prompt 29 (nestmate_behavior_relatedness): Output already exists.
2024-10-14 08:17:54,133 - INFO - Skipping Prompt 30 (colony_morphology_relatedness): Output already exists.
2024-10-14 08:17:54,133 - INFO - Skipping Prompt 31 (colony_behavior_morphology_relatedness): Output already exists.
2024-10-14 08:17:54,133 - INFO - Skipping Prompt 32 (nestmate_trait_relatedness_meta_analysis): Output already exists.
2024-10-14 08:17:54,133 - INFO - Skipping Prompt 33 (camponotus_recent_research): Output already exists.
2024-10-14 08:17:54,133 - INFO - Skipping Prompt 34 (formica_recent_studies): Output already exists.
2024-10-14 08:17:54,133 - INFO - Skipping Prompt 35 (pheidole_diversity_ecology): Output already exists.
2024-10-14 08:17:54,134 - INFO - Skipping Prompt 36 (atta_leafcutter_research): Output already exists.
2024-10-14 08:17:54,134 - INFO - Skipping Prompt 37 (solenopsis_fire_ant_studies): Output already exists.
2024-10-14 08:17:54,134 - INFO - Skipping Prompt 38 (monomorium_global_research): Output already exists.
2024-10-14 08:17:54,134 - INFO - Skipping Prompt 39 (lasius_ecosystem_interactions): Output already exists.
2024-10-14 08:17:54,134 - INFO - Skipping Prompt 40 (oecophylla_weaver_ant_research): Output already exists.
2024-10-14 08:17:54,134 - INFO - Skipping Prompt 41 (pogonomyrmex_barbatus_research): Output already exists.
2024-10-14 08:17:54,134 - INFO - Skipping Prompt 42 (non_barbatus_pogonomyrmex_studies): Output already exists.
2024-10-14 08:17:54,135 - INFO - Processing Prompt 43: Analyze recent research (2020-2024) on the impact ...
2024-10-14 08:18:35,467 - INFO - Prompt 43 processed successfully.
2024-10-14 08:18:35,467 - INFO - Time taken: 41.33 seconds
2024-10-14 08:18:35,467 - INFO - Output file: Markdown_Output/Prompt_43_northeastern_usa_urban_ants_20241014_081754.md
2024-10-14 08:18:38,469 - INFO - Processing Prompt 44: Review recent studies (2020-2024) on the effects o...
2024-10-14 08:19:32,305 - INFO - Prompt 44 processed successfully.
2024-10-14 08:19:32,305 - INFO - Time taken: 53.84 seconds
2024-10-14 08:19:32,305 - INFO - Output file: Markdown_Output/Prompt_44_southwestern_usa_climate_change_ants_20241014_081838.md
2024-10-14 08:19:35,306 - INFO - Processing Prompt 45: Conduct a meta-analysis of research from 2020-2024...
2024-10-14 08:20:18,644 - INFO - Prompt 45 processed successfully.
2024-10-14 08:20:18,644 - INFO - Time taken: 43.34 seconds
2024-10-14 08:20:18,644 - INFO - Output file: Markdown_Output/Prompt_45_pacific_northwest_ant_seed_dispersal_20241014_081935.md
2024-10-14 08:20:21,645 - INFO - Processing Prompt 46: Examine recent advancements (2020-2024) in the und...
2024-10-14 08:20:58,662 - INFO - Prompt 46 processed successfully.
2024-10-14 08:20:58,662 - INFO - Time taken: 37.02 seconds
2024-10-14 08:20:58,662 - INFO - Output file: Markdown_Output/Prompt_46_ant_chemical_communication_advances_20241014_082021.md
2024-10-14 08:21:01,663 - INFO - Processing Prompt 47: Analyze recent research (2020-2024) on the impact ...
2024-10-14 08:21:37,137 - INFO - Prompt 47 processed successfully.
2024-10-14 08:21:37,137 - INFO - Time taken: 35.47 seconds
2024-10-14 08:21:37,137 - INFO - Output file: Markdown_Output/Prompt_47_midwestern_usa_agricultural_ants_20241014_082101.md
2024-10-14 08:21:40,138 - INFO - All prompts processed.
